Workbook

Sheet kinematics
E1: Beam | J1: Mass
C2: symbol | D2: mass | E2: Energy | F2: E(c.m.) | I2: Z value | J2: excess | K2: Mass | N2: Q-value | Q2: This spreadsheet | U2: Mass
C3: (for neutron use nn) | E3: (MeV) | F3: (MeV) | J3: D (MeV) | K3: (amu) | Q3: for relativistic kinematics | U3: (MeV)
G4: energy is | Q4: was written by
B5: Beam | C5: Er | D5: 158 | E5: 616.2 | F5: =E5*K6/(K5+K6) -> 165.37984 | G5: =IF((F5+N10)>0,"above","BELOW") -> above | I5: =INDEX(Z_values,MATCH(C5,Symbol_values,0)) -> 68 | J5: ='mass_rmd.mas'!H2 -> -65.303808 | K5: ='mass_rmd.mas'!E2 -> 157.92989 | N5: g.s. | O5: final state | Q5: Wilton Catford | U5: ='mass_rmd.mas'!E2*'mass_rmd.mas'!A2 -> 147111.95
B6: Target | C6: Ni | D6: 58 | G6: threshold | I6: =INDEX(Z_values,MATCH(C6,Symbol_values,0)) -> 28 | J6: ='mass_rmd.mas'!H3 -> -60.228744 | K6: ='mass_rmd.mas'!E3 -> 57.935342 | N6: Reaction | O6: Reaction | Q6: Ó1998,2005, 2019 W.N. Catford | U6: ='mass_rmd.mas'!E3*'mass_rmd.mas'!A2 -> 53966.864
F7: Excitation | N7: Q-value | O7: Q-value
B8: Ejectile | C8: Ni | D8: 58 | F8: 0 | G8: MeV | I8: =INDEX(Z_values,MATCH(C8,Symbol_values,0)) -> 28 | J8: ='mass_rmd.mas'!H4 -> -60.228744 | K8: ='mass_rmd.mas'!E4 -> 57.935342 | N8: (MeV) | O8: (MeV) | Q8: w.catford@surrey.ac.uk | U8: ='mass_rmd.mas'!E4*'mass_rmd.mas'!A2+F8 -> 53966.864
B10: Recoil | C10: =INDEX(Symbol_values,MATCH(I10,Z_values,1)) -> Er | D10: =D5+D6-D8 -> 158 | F10: 1 | G10: MeV | I10: =I5+I6-I8 -> 68 | J10: ='mass_rmd.mas'!H5 -> -65.303808 | K10: ='mass_rmd.mas'!E5 -> 157.92989 | N10: =J5+J6-J8-J10 -> 0 | O10: =N10-F8-F10 -> -1 | Q10: "CatKIN" ver.2.03 | U10: ='mass_rmd.mas'!E5*'mass_rmd.mas'!A2+F10 -> 147112.95
N12: Second Solution
B13: Lab | D13: c.m. | F13: Lab | H13: cm/lab | J13: Recoil | L13: Recoil | N13: Lab | O13: c.m. | P13: Lab | Q13: cm/lab | R13: Recoil | S13: Recoil
B14: angle | D14: angle | F14: energy | H14: ratio | J14: angle | L14: energy | N14: angle | O14: angle | P14: energy | Q14: ratio | R14: angle | S14: energy | U14: y | V14: betac | W14: ecmi | X14: ecmf | Y14: e3cm | Z14: beta3c | AA14: y_new | AB14: cosagl | AC14: b | AD14: a | AE14: c | AF14: d**2 | AG14: b3L1 | AH14: y_loop | AI14: y_adj | AJ14: angl4 | AK14: b3L2 | AL14: y_loop2 | AM14: y_adj2 | AN14: angl4_2
A15: step | U15: =U5+U6 -> 201078.81 | V15: =SQRT(E5*(E5+2*U5))/(U15+E5) -> 0.066828076 | W15: =SQRT(U15*U15+(2*E5*U6)) -> 201244.12 | X15: =W15+O10-U15+U8+U10 -> 201244.12 | Y15: =(X15*X15+(U8+U10)*(U8-U10))/(2*X15) -> 54087.046 | Z15: =SQRT(1-1/(POWER(Y15/U8,2))) -> 0.066626431 | AA15: =POWER(Y15/U8,2)*(1-V15*V15) -> 0.99997297 | AE15: =1-AA15 -> 2.7030504e-05
A16: 5 | B16: 130 | D16: =IF(ISNUMBER(F16),IF(ABS(AI16-1)<0.000001,0,IF(ABS(AI16+1)<0.000001,180,ROUND(DEGREES(ACOS(AI16)),3)))," ") | F16: =IF(AG16>0.0000001,$U$8*((1/SQRT(1-AG16*AG16))-1),"none") -> none | H16: =IF(ISNUMBER(F16),$Z$15*(1+AC16/AG16)/(1+$V$15*$Z$15*AI16)/AG16," ") | J16: =IF(ISNUMBER(F16),IF( AND( ( (F16*(F16+2*$U$8)*AB16*AB16) > ($E$5*($E$5+2*$U$5)) ), ( B16<(90) ) ), 180-AJ16, AJ16)," ") | L16: =IF(ISNUMBER(F16),$E$5+$O$10-F16," ") | N16: =IF(ISNUMBER(P16),B16," ") | O16: =IF(ISNUMBER(P16), IF( ABS(AM16-1)<0.000001,0, IF(ABS(AM16+1)<0.000001,180,ROUND(DEGREES(ACOS(AM16)),3)))," ") | P16: =IF(AK16>0.0000001,$U$8*((1/SQRT(1-AK16*AK16))-1),"none") -> none | Q16: =IF(ISNUMBER(P16),ABS($Z$15*(1+AC16/AK16)/(1+$V$15*$Z$15*AM16)/AK16)," ") | R16: =IF(ISNUMBER(P16),IF( AND( ( (P16*(P16+2*$U$8)*AB16*AB16) > ($E$5*($E$5+2*$U$5)) ), ( B16<90 ) ), 180-AN16, AN16)," ") | S16: =IF(ISNUMBER(P16),$E$5+$O$10-P16," ") | AB16: =COS(RADIANS(B16)) -> -0.64278761 | AC16: =-$V$15*AB16 -> 0.042956259 | AD16: =$AA$15+AC16*AC16 -> 1.0018182 | AF16: =AC16*AC16-AD16*$AE$15 -> 0.0018181606 | AG16: =IF(ISNUMBER(SQRT(AF16)),(-AC16+SQRT(AF16))/AD16,-100) -> -0.00031579111 | AH16: =(AG16*AB16-$V$15)/((1-$V$15*AG16*AB16)*$Z$15) -> -0.99999344 | AI16: =IF(ABS(AH16)<=1,AH16,IF(ABS(AH16)<=1.00001,1*SIGN(AH16),0)) -> -0.99999344 | AJ16: =DEGREES(ASIN( SQRT( (F16*(F16+2*$U$8)) / (L16*(L16+2*$U$10)) ) * SIN(RADIANS(B16)) )) -> #VALUE! | AK16: =IF(ISNUMBER(SQRT(AF16)),(-AC16-SQRT(AF16))/AD16,-100) -> -0.085440804 | AL16: =(AK16*AB16-$V$15)/((1-$V$15*AK16*AB16)*$Z$15) -> -0.17938303 | AM16: =IF(ABS(AL16)<=1,AL16,IF(ABS(AL16)<=1.00001,1*SIGN(AL16),0)) -> -0.17938303 | AN16: =IF(ISNUMBER(P16),DEGREES(ASIN( SQRT( (P16*(P16+2*$U$8)) / (S16*(S16+2*$U$10)) ) * SIN(RADIANS(B16)) ) ),"ignore") -> ignore
B17: =B16+A16 -> 135 | D17: =IF(ISNUMBER(F17),IF(ABS(AI17-1)<0.000001,0,IF(ABS(AI17+1)<0.000001,180,ROUND(DEGREES(ACOS(AI17)),3)))," ") | F17: =IF(AG17>0.0000001,$U$8*((1/SQRT(1-AG17*AG17))-1),"none") -> none | H17: =IF(ISNUMBER(F17),$Z$15*(1+AC17/AG17)/(1+$V$15*$Z$15*AI17)/AG17," ") | J17: =IF(ISNUMBER(F17),IF( AND( ( (F17*(F17+2*$U$8)*AB17*AB17) > ($E$5*($E$5+2*$U$5)) ), ( B17<(90) ) ), 180-AJ17, AJ17)," ") | L17: =IF(ISNUMBER(F17),$E$5+$O$10-F17," ") | N17: =IF(ISNUMBER(P17),B17," ") | O17: =IF(ISNUMBER(P17), IF( ABS(AM17-1)<0.000001,0, IF(ABS(AM17+1)<0.000001,180,ROUND(DEGREES(ACOS(AM17)),3)))," ") | P17: =IF(AK17>0.0000001,$U$8*((1/SQRT(1-AK17*AK17))-1),"none") -> none | Q17: =IF(ISNUMBER(P17),ABS($Z$15*(1+AC17/AK17)/(1+$V$15*$Z$15*AM17)/AK17)," ") | R17: =IF(ISNUMBER(P17),IF( AND( ( (P17*(P17+2*$U$8)*AB17*AB17) > ($E$5*($E$5+2*$U$5)) ), ( B17<90 ) ), 180-AN17, AN17)," ") | S17: =IF(ISNUMBER(P17),$E$5+$O$10-P17," ") | AB17: =COS(RADIANS(B17)) -> -0.70710678 | AC17: =-$V$15*AB17 -> 0.047254586 | AD17: =$AA$15+AC17*AC17 -> 1.002206 | AF17: =AC17*AC17-AD17*$AE$15 -> 0.0022059058 | AG17: =IF(ISNUMBER(SQRT(AF17)),(-AC17+SQRT(AF17))/AD17,-100) -> -0.00028688207 | AH17: =(AG17*AB17-$V$15)/((1-$V$15*AG17*AB17)*$Z$15) -> -0.99999539 | AI17: =IF(ABS(AH17)<=1,AH17,IF(ABS(AH17)<=1.00001,1*SIGN(AH17),0)) -> -0.99999539 | AJ17: =DEGREES(ASIN( SQRT( (F17*(F17+2*$U$8)) / (L17*(L17+2*$U$10)) ) * SIN(RADIANS(B17)) )) -> #VALUE! | AK17: =IF(ISNUMBER(SQRT(AF17)),(-AC17-SQRT(AF17))/AD17,-100) -> -0.094014265 | AL17: =(AK17*AB17-$V$15)/((1-$V$15*AK17*AB17)*$Z$15) -> -0.0052758916 | AM17: =IF(ABS(AL17)<=1,AL17,IF(ABS(AL17)<=1.00001,1*SIGN(AL17),0)) -> -0.0052758916 | AN17: =IF(ISNUMBER(P17),DEGREES(ASIN( SQRT( (P17*(P17+2*$U$8)) / (S17*(S17+2*$U$10)) ) * SIN(RADIANS(B17)) ) ),"ignore") -> ignore
B18: =B16+A16*2 -> 140 | D18: =IF(ISNUMBER(F18),IF(ABS(AI18-1)<0.000001,0,IF(ABS(AI18+1)<0.000001,180,ROUND(DEGREES(ACOS(AI18)),3)))," ") | F18: =IF(AG18>0.0000001,$U$8*((1/SQRT(1-AG18*AG18))-1),"none") -> none | H18: =IF(ISNUMBER(F18),$Z$15*(1+AC18/AG18)/(1+$V$15*$Z$15*AI18)/AG18," ") | J18: =IF(ISNUMBER(F18),IF( AND( ( (F18*(F18+2*$U$8)*AB18*AB18) > ($E$5*($E$5+2*$U$5)) ), ( B18<(90) ) ), 180-AJ18, AJ18)," ") | L18: =IF(ISNUMBER(F18),$E$5+$O$10-F18," ") | N18: =IF(ISNUMBER(P18),B18," ") | O18: =IF(ISNUMBER(P18), IF( ABS(AM18-1)<0.000001,0, IF(ABS(AM18+1)<0.000001,180,ROUND(DEGREES(ACOS(AM18)),3)))," ") | P18: =IF(AK18>0.0000001,$U$8*((1/SQRT(1-AK18*AK18))-1),"none") -> none | Q18: =IF(ISNUMBER(P18),ABS($Z$15*(1+AC18/AK18)/(1+$V$15*$Z$15*AM18)/AK18)," ") | R18: =IF(ISNUMBER(P18),IF( AND( ( (P18*(P18+2*$U$8)*AB18*AB18) > ($E$5*($E$5+2*$U$5)) ), ( B18<90 ) ), 180-AN18, AN18)," ") | S18: =IF(ISNUMBER(P18),$E$5+$O$10-P18," ") | AB18: =COS(RADIANS(B18)) -> -0.76604444 | AC18: =-$V$15*AB18 -> 0.051193277 | AD18: =$AA$15+AC18*AC18 -> 1.0025937 | AF18: =AC18*AC18-AD18*$AE$15 -> 0.0025936509 | AG18: =IF(ISNUMBER(SQRT(AF18)),(-AC18+SQRT(AF18))/AD18,-100) -> -0.00026469049 | AH18: =(AG18*AB18-$V$15)/((1-$V$15*AG18*AB18)*$Z$15) -> -0.99999675 | AI18: =IF(ABS(AH18)<=1,AH18,IF(ABS(AH18)<=1.00001,1*SIGN(AH18),0)) -> -0.99999675 | AJ18: =DEGREES(ASIN( SQRT( (F18*(F18+2*$U$8)) / (L18*(L18+2*$U$10)) ) * SIN(RADIANS(B18)) )) -> #VALUE! | AK18: =IF(ISNUMBER(SQRT(AF18)),(-AC18-SQRT(AF18))/AD18,-100) -> -0.10185699 | AL18: =(AK18*AB18-$V$15)/((1-$V$15*AK18*AB18)*$Z$15) -> 0.16896604 | AM18: =IF(ABS(AL18)<=1,AL18,IF(ABS(AL18)<=1.00001,1*SIGN(AL18),0)) -> 0.16896604 | AN18: =IF(ISNUMBER(P18),DEGREES(ASIN( SQRT( (P18*(P18+2*$U$8)) / (S18*(S18+2*$U$10)) ) * SIN(RADIANS(B18)) ) ),"ignore") -> ignore
B19: =B16+A16*3 -> 145 | D19: =IF(ISNUMBER(F19),IF(ABS(AI19-1)<0.000001,0,IF(ABS(AI19+1)<0.000001,180,ROUND(DEGREES(ACOS(AI19)),3)))," ") | F19: =IF(AG19>0.0000001,$U$8*((1/SQRT(1-AG19*AG19))-1),"none") -> none | H19: =IF(ISNUMBER(F19),$Z$15*(1+AC19/AG19)/(1+$V$15*$Z$15*AI19)/AG19," ") | J19: =IF(ISNUMBER(F19),IF( AND( ( (F19*(F19+2*$U$8)*AB19*AB19) > ($E$5*($E$5+2*$U$5)) ), ( B19<(90) ) ), 180-AJ19, AJ19)," ") | L19: =IF(ISNUMBER(F19),$E$5+$O$10-F19," ") | N19: =IF(ISNUMBER(P19),B19," ") | O19: =IF(ISNUMBER(P19), IF( ABS(AM19-1)<0.000001,0, IF(ABS(AM19+1)<0.000001,180,ROUND(DEGREES(ACOS(AM19)),3)))," ") | P19: =IF(AK19>0.0000001,$U$8*((1/SQRT(1-AK19*AK19))-1),"none") -> none | Q19: =IF(ISNUMBER(P19),ABS($Z$15*(1+AC19/AK19)/(1+$V$15*$Z$15*AM19)/AK19)," ") | R19: =IF(ISNUMBER(P19),IF( AND( ( (P19*(P19+2*$U$8)*AB19*AB19) > ($E$5*($E$5+2*$U$5)) ), ( B19<90 ) ), 180-AN19, AN19)," ") | S19: =IF(ISNUMBER(P19),$E$5+$O$10-P19," ") | AB19: =COS(RADIANS(B19)) -> -0.81915204 | AC19: =-$V$15*AB19 -> 0.054742355 | AD19: =$AA$15+AC19*AC19 -> 1.0029697 | AF19: =AC19*AC19-AD19*$AE$15 -> 0.0029696147 | AG19: =IF(ISNUMBER(SQRT(AF19)),(-AC19+SQRT(AF19))/AD19,-100) -> -0.00024744932 | AH19: =(AG19*AB19-$V$15)/((1-$V$15*AG19*AB19)*$Z$15) -> -0.99999774 | AI19: =IF(ABS(AH19)<=1,AH19,IF(ABS(AH19)<=1.00001,1*SIGN(AH19),0)) -> -0.99999774 | AJ19: =DEGREES(ASIN( SQRT( (F19*(F19+2*$U$8)) / (L19*(L19+2*$U$10)) ) * SIN(RADIANS(B19)) )) -> #VALUE! | AK19: =IF(ISNUMBER(SQRT(AF19)),(-AC19-SQRT(AF19))/AD19,-100) -> -0.10891309 | AL19: =(AK19*AB19-$V$15)/((1-$V$15*AK19*AB19)*$Z$15) -> 0.3380428 | AM19: =IF(ABS(AL19)<=1,AL19,IF(ABS(AL19)<=1.00001,1*SIGN(AL19),0)) -> 0.3380428 | AN19: =IF(ISNUMBER(P19),DEGREES(ASIN( SQRT( (P19*(P19+2*$U$8)) / (S19*(S19+2*$U$10)) ) * SIN(RADIANS(B19)) ) ),"ignore") -> ignore
B20: =B16+A16*4 -> 150 | D20: =IF(ISNUMBER(F20),IF(ABS(AI20-1)<0.000001,0,IF(ABS(AI20+1)<0.000001,180,ROUND(DEGREES(ACOS(AI20)),3)))," ") | F20: =IF(AG20>0.0000001,$U$8*((1/SQRT(1-AG20*AG20))-1),"none") -> none | H20: =IF(ISNUMBER(F20),$Z$15*(1+AC20/AG20)/(1+$V$15*$Z$15*AI20)/AG20," ") | J20: =IF(ISNUMBER(F20),IF( AND( ( (F20*(F20+2*$U$8)*AB20*AB20) > ($E$5*($E$5+2*$U$5)) ), ( B20<(90) ) ), 180-AJ20, AJ20)," ") | L20: =IF(ISNUMBER(F20),$E$5+$O$10-F20," ") | N20: =IF(ISNUMBER(P20),B20," ") | O20: =IF(ISNUMBER(P20), IF( ABS(AM20-1)<0.000001,0, IF(ABS(AM20+1)<0.000001,180,ROUND(DEGREES(ACOS(AM20)),3)))," ") | P20: =IF(AK20>0.0000001,$U$8*((1/SQRT(1-AK20*AK20))-1),"none") -> none | Q20: =IF(ISNUMBER(P20),ABS($Z$15*(1+AC20/AK20)/(1+$V$15*$Z$15*AM20)/AK20)," ") | R20: =IF(ISNUMBER(P20),IF( AND( ( (P20*(P20+2*$U$8)*AB20*AB20) > ($E$5*($E$5+2*$U$5)) ), ( B20<90 ) ), 180-AN20, AN20)," ") | S20: =IF(ISNUMBER(P20),$E$5+$O$10-P20," ") | AB20: =COS(RADIANS(B20)) -> -0.8660254 | AC20: =-$V$15*AB20 -> 0.057874812 | AD20: =$AA$15+AC20*AC20 -> 1.0033225 | AF20: =AC20*AC20-AD20*$AE$15 -> 0.0033223735 | AG20: =IF(ISNUMBER(SQRT(AF20)),(-AC20+SQRT(AF20))/AD20,-100) -> -0.00023400026 | AH20: =(AG20*AB20-$V$15)/((1-$V$15*AG20*AB20)*$Z$15) -> -0.99999846 | AI20: =IF(ABS(AH20)<=1,AH20,IF(ABS(AH20)<=1.00001,1*SIGN(AH20),0)) -> -0.99999846 | AJ20: =DEGREES(ASIN( SQRT( (F20*(F20+2*$U$8)) / (L20*(L20+2*$U$10)) ) * SIN(RADIANS(B20)) )) -> #VALUE! | AK20: =IF(ISNUMBER(SQRT(AF20)),(-AC20-SQRT(AF20))/AD20,-100) -> -0.11513232 | AL20: =(AK20*AB20-$V$15)/((1-$V$15*AK20*AB20)*$Z$15) -> 0.49679975 | AM20: =IF(ABS(AL20)<=1,AL20,IF(ABS(AL20)<=1.00001,1*SIGN(AL20),0)) -> 0.49679975 | AN20: =IF(ISNUMBER(P20),DEGREES(ASIN( SQRT( (P20*(P20+2*$U$8)) / (S20*(S20+2*$U$10)) ) * SIN(RADIANS(B20)) ) ),"ignore") -> ignore
B21: =B16+A16*5 -> 155 | D21: =IF(ISNUMBER(F21),IF(ABS(AI21-1)<0.000001,0,IF(ABS(AI21+1)<0.000001,180,ROUND(DEGREES(ACOS(AI21)),3)))," ") | F21: =IF(AG21>0.0000001,$U$8*((1/SQRT(1-AG21*AG21))-1),"none") -> none | H21: =IF(ISNUMBER(F21),$Z$15*(1+AC21/AG21)/(1+$V$15*$Z$15*AI21)/AG21," ") | J21: =IF(ISNUMBER(F21),IF( AND( ( (F21*(F21+2*$U$8)*AB21*AB21) > ($E$5*($E$5+2*$U$5)) ), ( B21<(90) ) ), 180-AJ21, AJ21)," ") | L21: =IF(ISNUMBER(F21),$E$5+$O$10-F21," ") | N21: =IF(ISNUMBER(P21),B21," ") | O21: =IF(ISNUMBER(P21), IF( ABS(AM21-1)<0.000001,0, IF(ABS(AM21+1)<0.000001,180,ROUND(DEGREES(ACOS(AM21)),3)))," ") | P21: =IF(AK21>0.0000001,$U$8*((1/SQRT(1-AK21*AK21))-1),"none") -> none | Q21: =IF(ISNUMBER(P21),ABS($Z$15*(1+AC21/AK21)/(1+$V$15*$Z$15*AM21)/AK21)," ") | R21: =IF(ISNUMBER(P21),IF( AND( ( (P21*(P21+2*$U$8)*AB21*AB21) > ($E$5*($E$5+2*$U$5)) ), ( B21<90 ) ), 180-AN21, AN21)," ") | S21: =IF(ISNUMBER(P21),$E$5+$O$10-P21," ") | AB21: =COS(RADIANS(B21)) -> -0.90630779 | AC21: =-$V$15*AB21 -> 0.060566806 | AD21: =$AA$15+AC21*AC21 -> 1.0036413 | AF21: =AC21*AC21-AD21*$AE$15 -> 0.0036412091 | AG21: =IF(ISNUMBER(SQRT(AF21)),(-AC21+SQRT(AF21))/AD21,-100) -> -0.00022356029 | AH21: =(AG21*AB21-$V$15)/((1-$V$15*AG21*AB21)*$Z$15) -> -0.999999 | AI21: =IF(ABS(AH21)<=1,AH21,IF(ABS(AH21)<=1.00001,1*SIGN(AH21),0)) -> -0.999999 | AJ21: =DEGREES(ASIN( SQRT( (F21*(F21+2*$U$8)) / (L21*(L21+2*$U$10)) ) * SIN(RADIANS(B21)) )) -> #VALUE! | AK21: =IF(ISNUMBER(SQRT(AF21)),(-AC21-SQRT(AF21))/AD21,-100) -> -0.12047057 | AL21: =(AK21*AB21-$V$15)/((1-$V$15*AK21*AB21)*$Z$15) -> 0.64038632 | AM21: =IF(ABS(AL21)<=1,AL21,IF(ABS(AL21)<=1.00001,1*SIGN(AL21),0)) -> 0.64038632 | AN21: =IF(ISNUMBER(P21),DEGREES(ASIN( SQRT( (P21*(P21+2*$U$8)) / (S21*(S21+2*$U$10)) ) * SIN(RADIANS(B21)) ) ),"ignore") -> ignore
B22: =B16+A16*6 -> 160 | D22: =IF(ISNUMBER(F22),IF(ABS(AI22-1)<0.000001,0,IF(ABS(AI22+1)<0.000001,180,ROUND(DEGREES(ACOS(AI22)),3)))," ") | F22: =IF(AG22>0.0000001,$U$8*((1/SQRT(1-AG22*AG22))-1),"none") -> none | H22: =IF(ISNUMBER(F22),$Z$15*(1+AC22/AG22)/(1+$V$15*$Z$15*AI22)/AG22," ") | J22: =IF(ISNUMBER(F22),IF( AND( ( (F22*(F22+2*$U$8)*AB22*AB22) > ($E$5*($E$5+2*$U$5)) ), ( B22<(90) ) ), 180-AJ22, AJ22)," ") | L22: =IF(ISNUMBER(F22),$E$5+$O$10-F22," ") | N22: =IF(ISNUMBER(P22),B22," ") | O22: =IF(ISNUMBER(P22), IF( ABS(AM22-1)<0.000001,0, IF(ABS(AM22+1)<0.000001,180,ROUND(DEGREES(ACOS(AM22)),3)))," ") | P22: =IF(AK22>0.0000001,$U$8*((1/SQRT(1-AK22*AK22))-1),"none") -> none | Q22: =IF(ISNUMBER(P22),ABS($Z$15*(1+AC22/AK22)/(1+$V$15*$Z$15*AM22)/AK22)," ") | R22: =IF(ISNUMBER(P22),IF( AND( ( (P22*(P22+2*$U$8)*AB22*AB22) > ($E$5*($E$5+2*$U$5)) ), ( B22<90 ) ), 180-AN22, AN22)," ") | S22: =IF(ISNUMBER(P22),$E$5+$O$10-P22," ") | AB22: =COS(RADIANS(B22)) -> -0.93969262 | AC22: =-$V$15*AB22 -> 0.06279785 | AD22: =$AA$15+AC22*AC22 -> 1.0039165 | AF22: =AC22*AC22-AD22*$AE$15 -> 0.0039164336 | AG22: =IF(ISNUMBER(SQRT(AF22)),(-AC22+SQRT(AF22))/AD22,-100) -> -0.0002155899 | AH22: =(AG22*AB22-$V$15)/((1-$V$15*AG22*AB22)*$Z$15) -> -0.99999939 | AI22: =IF(ABS(AH22)<=1,AH22,IF(ABS(AH22)<=1.00001,1*SIGN(AH22),0)) -> -0.99999939 | AJ22: =DEGREES(ASIN( SQRT( (F22*(F22+2*$U$8)) / (L22*(L22+2*$U$10)) ) * SIN(RADIANS(B22)) )) -> #VALUE! | AK22: =IF(ISNUMBER(SQRT(AF22)),(-AC22-SQRT(AF22))/AD22,-100) -> -0.12489013 | AL22: =(AK22*AB22-$V$15)/((1-$V$15*AK22*AB22)*$Z$15) -> 0.76440669 | AM22: =IF(ABS(AL22)<=1,AL22,IF(ABS(AL22)<=1.00001,1*SIGN(AL22),0)) -> 0.76440669 | AN22: =IF(ISNUMBER(P22),DEGREES(ASIN( SQRT( (P22*(P22+2*$U$8)) / (S22*(S22+2*$U$10)) ) * SIN(RADIANS(B22)) ) ),"ignore") -> ignore
B23: =B16+A16*7 -> 165 | D23: =IF(ISNUMBER(F23),IF(ABS(AI23-1)<0.000001,0,IF(ABS(AI23+1)<0.000001,180,ROUND(DEGREES(ACOS(AI23)),3)))," ") | F23: =IF(AG23>0.0000001,$U$8*((1/SQRT(1-AG23*AG23))-1),"none") -> none | H23: =IF(ISNUMBER(F23),$Z$15*(1+AC23/AG23)/(1+$V$15*$Z$15*AI23)/AG23," ") | J23: =IF(ISNUMBER(F23),IF( AND( ( (F23*(F23+2*$U$8)*AB23*AB23) > ($E$5*($E$5+2*$U$5)) ), ( B23<(90) ) ), 180-AJ23, AJ23)," ") | L23: =IF(ISNUMBER(F23),$E$5+$O$10-F23," ") | N23: =IF(ISNUMBER(P23),B23," ") | O23: =IF(ISNUMBER(P23), IF( ABS(AM23-1)<0.000001,0, IF(ABS(AM23+1)<0.000001,180,ROUND(DEGREES(ACOS(AM23)),3)))," ") | P23: =IF(AK23>0.0000001,$U$8*((1/SQRT(1-AK23*AK23))-1),"none") -> none | Q23: =IF(ISNUMBER(P23),ABS($Z$15*(1+AC23/AK23)/(1+$V$15*$Z$15*AM23)/AK23)," ") | R23: =IF(ISNUMBER(P23),IF( AND( ( (P23*(P23+2*$U$8)*AB23*AB23) > ($E$5*($E$5+2*$U$5)) ), ( B23<90 ) ), 180-AN23, AN23)," ") | S23: =IF(ISNUMBER(P23),$E$5+$O$10-P23," ") | AB23: =COS(RADIANS(B23)) -> -0.96592583 | AC23: =-$V$15*AB23 -> 0.064550965 | AD23: =$AA$15+AC23*AC23 -> 1.0041398 | AF23: =AC23*AC23-AD23*$AE$15 -> 0.0041396847 | AG23: =IF(ISNUMBER(SQRT(AF23)),(-AC23+SQRT(AF23))/AD23,-100) -> -0.00020971543 | AH23: =(AG23*AB23-$V$15)/((1-$V$15*AG23*AB23)*$Z$15) -> -0.99999967 | AI23: =IF(ABS(AH23)<=1,AH23,IF(ABS(AH23)<=1.00001,1*SIGN(AH23),0)) -> -0.99999967 | AJ23: =DEGREES(ASIN( SQRT( (F23*(F23+2*$U$8)) / (L23*(L23+2*$U$10)) ) * SIN(RADIANS(B23)) )) -> #VALUE! | AK23: =IF(ISNUMBER(SQRT(AF23)),(-AC23-SQRT(AF23))/AD23,-100) -> -0.12835996 | AL23: =(AK23*AB23-$V$15)/((1-$V$15*AK23*AB23)*$Z$15) -> 0.86505732 | AM23: =IF(ABS(AL23)<=1,AL23,IF(ABS(AL23)<=1.00001,1*SIGN(AL23),0)) -> 0.86505732 | AN23: =IF(ISNUMBER(P23),DEGREES(ASIN( SQRT( (P23*(P23+2*$U$8)) / (S23*(S23+2*$U$10)) ) * SIN(RADIANS(B23)) ) ),"ignore") -> ignore
B24: =B16+A16*8 -> 170 | D24: =IF(ISNUMBER(F24),IF(ABS(AI24-1)<0.000001,0,IF(ABS(AI24+1)<0.000001,180,ROUND(DEGREES(ACOS(AI24)),3)))," ") | F24: =IF(AG24>0.0000001,$U$8*((1/SQRT(1-AG24*AG24))-1),"none") -> none | H24: =IF(ISNUMBER(F24),$Z$15*(1+AC24/AG24)/(1+$V$15*$Z$15*AI24)/AG24," ") | J24: =IF(ISNUMBER(F24),IF( AND( ( (F24*(F24+2*$U$8)*AB24*AB24) > ($E$5*($E$5+2*$U$5)) ), ( B24<(90) ) ), 180-AJ24, AJ24)," ") | L24: =IF(ISNUMBER(F24),$E$5+$O$10-F24," ") | N24: =IF(ISNUMBER(P24),B24," ") | O24: =IF(ISNUMBER(P24), IF( ABS(AM24-1)<0.000001,0, IF(ABS(AM24+1)<0.000001,180,ROUND(DEGREES(ACOS(AM24)),3)))," ") | P24: =IF(AK24>0.0000001,$U$8*((1/SQRT(1-AK24*AK24))-1),"none") -> none | Q24: =IF(ISNUMBER(P24),ABS($Z$15*(1+AC24/AK24)/(1+$V$15*$Z$15*AM24)/AK24)," ") | R24: =IF(ISNUMBER(P24),IF( AND( ( (P24*(P24+2*$U$8)*AB24*AB24) > ($E$5*($E$5+2*$U$5)) ), ( B24<90 ) ), 180-AN24, AN24)," ") | S24: =IF(ISNUMBER(P24),$E$5+$O$10-P24," ") | AB24: =COS(RADIANS(B24)) -> -0.98480775 | AC24: =-$V$15*AB24 -> 0.065812808 | AD24: =$AA$15+AC24*AC24 -> 1.0043043 | AF24: =AC24*AC24-AD24*$AE$15 -> 0.0043041788 | AG24: =IF(ISNUMBER(SQRT(AF24)),(-AC24+SQRT(AF24))/AD24,-100) -> -0.00020568178 | AH24: =(AG24*AB24-$V$15)/((1-$V$15*AG24*AB24)*$Z$15) -> -0.99999986 | AI24: =IF(ABS(AH24)<=1,AH24,IF(ABS(AH24)<=1.00001,1*SIGN(AH24),0)) -> -0.99999986 | AJ24: =DEGREES(ASIN( SQRT( (F24*(F24+2*$U$8)) / (L24*(L24+2*$U$10)) ) * SIN(RADIANS(B24)) )) -> #VALUE! | AK24: =IF(ISNUMBER(SQRT(AF24)),(-AC24-SQRT(AF24))/AD24,-100) -> -0.13085581 | AL24: =(AK24*AB24-$V$15)/((1-$V$15*AK24*AB24)*$Z$15) -> 0.93924682 | AM24: =IF(ABS(AL24)<=1,AL24,IF(ABS(AL24)<=1.00001,1*SIGN(AL24),0)) -> 0.93924682 | AN24: =IF(ISNUMBER(P24),DEGREES(ASIN( SQRT( (P24*(P24+2*$U$8)) / (S24*(S24+2*$U$10)) ) * SIN(RADIANS(B24)) ) ),"ignore") -> ignore
B25: =B16+A16*9 -> 175 | D25: =IF(ISNUMBER(F25),IF(ABS(AI25-1)<0.000001,0,IF(ABS(AI25+1)<0.000001,180,ROUND(DEGREES(ACOS(AI25)),3)))," ") | F25: =IF(AG25>0.0000001,$U$8*((1/SQRT(1-AG25*AG25))-1),"none") -> none | H25: =IF(ISNUMBER(F25),$Z$15*(1+AC25/AG25)/(1+$V$15*$Z$15*AI25)/AG25," ") | J25: =IF(ISNUMBER(F25),IF( AND( ( (F25*(F25+2*$U$8)*AB25*AB25) > ($E$5*($E$5+2*$U$5)) ), ( B25<(90) ) ), 180-AJ25, AJ25)," ") | L25: =IF(ISNUMBER(F25),$E$5+$O$10-F25," ") | N25: =IF(ISNUMBER(P25),B25," ") | O25: =IF(ISNUMBER(P25), IF( ABS(AM25-1)<0.000001,0, IF(ABS(AM25+1)<0.000001,180,ROUND(DEGREES(ACOS(AM25)),3)))," ") | P25: =IF(AK25>0.0000001,$U$8*((1/SQRT(1-AK25*AK25))-1),"none") -> none | Q25: =IF(ISNUMBER(P25),ABS($Z$15*(1+AC25/AK25)/(1+$V$15*$Z$15*AM25)/AK25)," ") | R25: =IF(ISNUMBER(P25),IF( AND( ( (P25*(P25+2*$U$8)*AB25*AB25) > ($E$5*($E$5+2*$U$5)) ), ( B25<90 ) ), 180-AN25, AN25)," ") | S25: =IF(ISNUMBER(P25),$E$5+$O$10-P25," ") | AB25: =COS(RADIANS(B25)) -> -0.9961947 | AC25: =-$V$15*AB25 -> 0.066573775 | AD25: =$AA$15+AC25*AC25 -> 1.004405 | AF25: =AC25*AC25-AD25*$AE$15 -> 0.004404918 | AG25: =IF(ISNUMBER(SQRT(AF25)),(-AC25+SQRT(AF25))/AD25,-100) -> -0.0002033235 | AH25: =(AG25*AB25-$V$15)/((1-$V$15*AG25*AB25)*$Z$15) -> -0.99999996 | AI25: =IF(ABS(AH25)<=1,AH25,IF(ABS(AH25)<=1.00001,1*SIGN(AH25),0)) -> -0.99999996 | AJ25: =DEGREES(ASIN( SQRT( (F25*(F25+2*$U$8)) / (L25*(L25+2*$U$10)) ) * SIN(RADIANS(B25)) )) -> #VALUE! | AK25: =IF(ISNUMBER(SQRT(AF25)),(-AC25-SQRT(AF25))/AD25,-100) -> -0.13236028 | AL25: =(AK25*AB25-$V$15)/((1-$V$15*AK25*AB25)*$Z$15) -> 0.9846939 | AM25: =IF(ABS(AL25)<=1,AL25,IF(ABS(AL25)<=1.00001,1*SIGN(AL25),0)) -> 0.9846939 | AN25: =IF(ISNUMBER(P25),DEGREES(ASIN( SQRT( (P25*(P25+2*$U$8)) / (S25*(S25+2*$U$10)) ) * SIN(RADIANS(B25)) ) ),"ignore") -> ignore
B26: =B16+A16*10 -> 180 | D26: =IF(ISNUMBER(F26),IF(ABS(AI26-1)<0.000001,0,IF(ABS(AI26+1)<0.000001,180,ROUND(DEGREES(ACOS(AI26)),3)))," ") | F26: =IF(AG26>0.0000001,$U$8*((1/SQRT(1-AG26*AG26))-1),"none") -> none | H26: =IF(ISNUMBER(F26),$Z$15*(1+AC26/AG26)/(1+$V$15*$Z$15*AI26)/AG26," ") | J26: =IF(ISNUMBER(F26),IF( AND( ( (F26*(F26+2*$U$8)*AB26*AB26) > ($E$5*($E$5+2*$U$5)) ), ( B26<(90) ) ), 180-AJ26, AJ26)," ") | L26: =IF(ISNUMBER(F26),$E$5+$O$10-F26," ") | N26: =IF(ISNUMBER(P26),B26," ") | O26: =IF(ISNUMBER(P26), IF( ABS(AM26-1)<0.000001,0, IF(ABS(AM26+1)<0.000001,180,ROUND(DEGREES(ACOS(AM26)),3)))," ") | P26: =IF(AK26>0.0000001,$U$8*((1/SQRT(1-AK26*AK26))-1),"none") -> none | Q26: =IF(ISNUMBER(P26),ABS($Z$15*(1+AC26/AK26)/(1+$V$15*$Z$15*AM26)/AK26)," ") | R26: =IF(ISNUMBER(P26),IF( AND( ( (P26*(P26+2*$U$8)*AB26*AB26) > ($E$5*($E$5+2*$U$5)) ), ( B26<90 ) ), 180-AN26, AN26)," ") | S26: =IF(ISNUMBER(P26),$E$5+$O$10-P26," ") | AB26: =COS(RADIANS(B26)) -> -1 | AC26: =-$V$15*AB26 -> 0.066828076 | AD26: =$AA$15+AC26*AC26 -> 1.004439 | AF26: =AC26*AC26-AD26*$AE$15 -> 0.0044388413 | AG26: =IF(ISNUMBER(SQRT(AF26)),(-AC26+SQRT(AF26))/AD26,-100) -> -0.00020254744 | AH26: =(AG26*AB26-$V$15)/((1-$V$15*AG26*AB26)*$Z$15) -> -1 | AI26: =IF(ABS(AH26)<=1,AH26,IF(ABS(AH26)<=1.00001,1*SIGN(AH26),0)) -> -1 | AJ26: =DEGREES(ASIN( SQRT( (F26*(F26+2*$U$8)) / (L26*(L26+2*$U$10)) ) * SIN(RADIANS(B26)) )) -> #VALUE! | AK26: =IF(ISNUMBER(SQRT(AF26)),(-AC26-SQRT(AF26))/AD26,-100) -> -0.13286293 | AL26: =(AK26*AB26-$V$15)/((1-$V$15*AK26*AB26)*$Z$15) -> 1 | AM26: =IF(ABS(AL26)<=1,AL26,IF(ABS(AL26)<=1.00001,1*SIGN(AL26),0)) -> 1 | AN26: =IF(ISNUMBER(P26),DEGREES(ASIN( SQRT( (P26*(P26+2*$U$8)) / (S26*(S26+2*$U$10)) ) * SIN(RADIANS(B26)) ) ),"ignore") -> ignore
B30: 0 | D30: =IF(ISNUMBER(F30),IF(ABS(AI30-1)<0.000001,0,IF(ABS(AI30+1)<0.000001,180,ROUND(DEGREES(ACOS(AI30)),3)))," ") -> 0 | F30: =IF(AG30>0.0000001,$U$8*((1/SQRT(1-AG30*AG30))-1),"none") -> 482.72714 | H30: =IF(ISNUMBER(F30),$Z$15*(1+AC30/AG30)/(1+$V$15*$Z$15*AI30)/AG30," ") -> 0.24813196 | J30: =IF(ISNUMBER(F30),IF( AND( ( (F30*(F30+2*$U$8)*AB30*AB30) > ($E$5*($E$5+2*$U$5)) ), ( B30<90 ) ), 180-AJ30, AJ30)," ") -> 0 | L30: =IF(ISNUMBER(F30),$E$5+$O$10-F30," ") -> 132.47286 | N30: =IF(ISNUMBER(P30),B30," ") -> 0 | O30: =IF(ISNUMBER(P30), IF( ABS(AM30-1)<0.000001,0, IF(ABS(AM30+1)<0.000001,180,ROUND(DEGREES(ACOS(AM30)),3)))," ") -> 180 | P30: =IF(AK30>0.0000001,$U$8*((1/SQRT(1-AK30*AK30))-1),"none") -> 0.0011070079 | Q30: =IF(ISNUMBER(P30),ABS($Z$15*(1+AC30/AK30)/(1+$V$15*$Z$15*AM30)/AK30)," ") -> 108685.53 | R30: =IF(ISNUMBER(P30),IF( AND( ( (P30*(P30+2*$U$8)*AB30*AB30) > ($E$5*($E$5+2*$U$5)) ), ( B30<90 ) ), 180-AN30, AN30)," ") -> 0 | S30: =IF(ISNUMBER(P30),$E$5+$O$10-P30," ") -> 615.19889 | AB30: =COS(RADIANS(B30)) -> 1 | AC30: =-$V$15*AB30 -> -0.066828076 | AD30: =$AA$15+AC30*AC30 -> 1.004439 | AF30: =AC30*AC30-AD30*$AE$15 -> 0.0044388413 | AG30: =IF(ISNUMBER(SQRT(AF30)),(-AC30+SQRT(AF30))/AD30,-100) -> 0.13286293 | AH30: =(AG30*AB30-$V$15)/((1-$V$15*AG30*AB30)*$Z$15) -> 1 | AI30: =IF(ABS(AH30)<=1,AH30,IF(ABS(AH30)<=1.00001,1*SIGN(AH30),0)) -> 1 | AJ30: =DEGREES(ASIN( SQRT( (F30*(F30+2*$U$8)) / (L30*(L30+2*$U$10)) ) * SIN(RADIANS(B30)) )) -> 0 | AK30: =IF(ISNUMBER(SQRT(AF30)),(-AC30-SQRT(AF30))/AD30,-100) -> 0.00020254744 | AL30: =(AK30*AB30-$V$15)/((1-$V$15*AK30*AB30)*$Z$15) -> -1 | AM30: =IF(ABS(AL30)<=1,AL30,IF(ABS(AL30)<=1.00001,1*SIGN(AL30),0)) -> -1 | AN30: =IF(ISNUMBER(P30),DEGREES(ASIN( SQRT( (P30*(P30+2*$U$8)) / (S30*(S30+2*$U$10)) ) * SIN(RADIANS(B30)) ) ),"ignore") -> 0
B31: 1 | D31: =IF(ISNUMBER(F31),IF(ABS(AI31-1)<0.000001,0,IF(ABS(AI31+1)<0.000001,180,ROUND(DEGREES(ACOS(AI31)),3)))," ") -> 2.008 | F31: =IF(AG31>0.0000001,$U$8*((1/SQRT(1-AG31*AG31))-1),"none") -> 482.579 | H31: =IF(ISNUMBER(F31),$Z$15*(1+AC31/AG31)/(1+$V$15*$Z$15*AI31)/AG31," ") -> 0.24817044 | J31: =IF(ISNUMBER(F31),IF( AND( ( (F31*(F31+2*$U$8)*AB31*AB31) > ($E$5*($E$5+2*$U$5)) ), ( B31<90 ) ), 180-AJ31, AJ31)," ") -> 1.1576961 | L31: =IF(ISNUMBER(F31),$E$5+$O$10-F31," ") -> 132.621 | N31: =IF(ISNUMBER(P31),B31," ") -> 1 | O31: =IF(ISNUMBER(P31), IF( ABS(AM31-1)<0.000001,0, IF(ABS(AM31+1)<0.000001,180,ROUND(DEGREES(ACOS(AM31)),3)))," ") -> 180 | P31: =IF(AK31>0.0000001,$U$8*((1/SQRT(1-AK31*AK31))-1),"none") -> 0.0011073462 | Q31: =IF(ISNUMBER(P31),ABS($Z$15*(1+AC31/AK31)/(1+$V$15*$Z$15*AM31)/AK31)," ") -> 108635.67 | R31: =IF(ISNUMBER(P31),IF( AND( ( (P31*(P31+2*$U$8)*AB31*AB31) > ($E$5*($E$5+2*$U$5)) ), ( B31<90 ) ), 180-AN31, AN31)," ") -> 0.00081170173 | S31: =IF(ISNUMBER(P31),$E$5+$O$10-P31," ") -> 615.19889 | AB31: =COS(RADIANS(B31)) -> 0.9998477 | AC31: =-$V$15*AB31 -> -0.066817898 | AD31: =$AA$15+AC31*AC31 -> 1.0044376 | AF31: =AC31*AC31-AD31*$AE$15 -> 0.0044374811 | AG31: =IF(ISNUMBER(SQRT(AF31)),(-AC31+SQRT(AF31))/AD31,-100) -> 0.13284282 | AH31: =(AG31*AB31-$V$15)/((1-$V$15*AG31*AB31)*$Z$15) -> 0.99938624 | AI31: =IF(ABS(AH31)<=1,AH31,IF(ABS(AH31)<=1.00001,1*SIGN(AH31),0)) -> 0.99938624 | AJ31: =DEGREES(ASIN( SQRT( (F31*(F31+2*$U$8)) / (L31*(L31+2*$U$10)) ) * SIN(RADIANS(B31)) )) -> 1.1576961 | AK31: =IF(ISNUMBER(SQRT(AF31)),(-AC31-SQRT(AF31))/AD31,-100) -> 0.00020257839 | AL31: =(AK31*AB31-$V$15)/((1-$V$15*AK31*AB31)*$Z$15) -> -1 | AM31: =IF(ABS(AL31)<=1,AL31,IF(ABS(AL31)<=1.00001,1*SIGN(AL31),0)) -> -1 | AN31: =IF(ISNUMBER(P31),DEGREES(ASIN( SQRT( (P31*(P31+2*$U$8)) / (S31*(S31+2*$U$10)) ) * SIN(RADIANS(B31)) ) ),"ignore") -> 0.00081170173
B32: 2 | D32: =IF(ISNUMBER(F32),IF(ABS(AI32-1)<0.000001,0,IF(ABS(AI32+1)<0.000001,180,ROUND(DEGREES(ACOS(AI32)),3)))," ") -> 4.015 | F32: =IF(AG32>0.0000001,$U$8*((1/SQRT(1-AG32*AG32))-1),"none") -> 482.13476 | H32: =IF(ISNUMBER(F32),$Z$15*(1+AC32/AG32)/(1+$V$15*$Z$15*AI32)/AG32," ") -> 0.24828592 | J32: =IF(ISNUMBER(F32),IF( AND( ( (F32*(F32+2*$U$8)*AB32*AB32) > ($E$5*($E$5+2*$U$5)) ), ( B32<90 ) ), 180-AJ32, AJ32)," ") -> 2.3105705 | L32: =IF(ISNUMBER(F32),$E$5+$O$10-F32," ") -> 133.06524 | N32: =IF(ISNUMBER(P32),B32," ") -> 2 | O32: =IF(ISNUMBER(P32), IF( ABS(AM32-1)<0.000001,0, IF(ABS(AM32+1)<0.000001,180,ROUND(DEGREES(ACOS(AM32)),3)))," ") -> 180 | P32: =IF(AK32>0.0000001,$U$8*((1/SQRT(1-AK32*AK32))-1),"none") -> 0.0011083619 | Q32: =IF(ISNUMBER(P32),ABS($Z$15*(1+AC32/AK32)/(1+$V$15*$Z$15*AM32)/AK32)," ") -> 108486.22 | R32: =IF(ISNUMBER(P32),IF( AND( ( (P32*(P32+2*$U$8)*AB32*AB32) > ($E$5*($E$5+2*$U$5)) ), ( B32<90 ) ), 180-AN32, AN32)," ") -> 0.0016239005 | S32: =IF(ISNUMBER(P32),$E$5+$O$10-P32," ") -> 615.19889 | AB32: =COS(RADIANS(B32)) -> 0.99939083 | AC32: =-$V$15*AB32 -> -0.066787366 | AD32: =$AA$15+AC32*AC32 -> 1.0044335 | AF32: =AC32*AC32-AD32*$AE$15 -> 0.004433402 | AG32: =IF(ISNUMBER(SQRT(AF32)),(-AC32+SQRT(AF32))/AD32,-100) -> 0.13278247 | AH32: =(AG32*AB32-$V$15)/((1-$V$15*AG32*AB32)*$Z$15) -> 0.99754572 | AI32: =IF(ABS(AH32)<=1,AH32,IF(ABS(AH32)<=1.00001,1*SIGN(AH32),0)) -> 0.99754572 | AJ32: =DEGREES(ASIN( SQRT( (F32*(F32+2*$U$8)) / (L32*(L32+2*$U$10)) ) * SIN(RADIANS(B32)) )) -> 2.3105705 | AK32: =IF(ISNUMBER(SQRT(AF32)),(-AC32-SQRT(AF32))/AD32,-100) -> 0.00020267128 | AL32: =(AK32*AB32-$V$15)/((1-$V$15*AK32*AB32)*$Z$15) -> -0.99999999 | AM32: =IF(ABS(AL32)<=1,AL32,IF(ABS(AL32)<=1.00001,1*SIGN(AL32),0)) -> -0.99999999 | AN32: =IF(ISNUMBER(P32),DEGREES(ASIN( SQRT( (P32*(P32+2*$U$8)) / (S32*(S32+2*$U$10)) ) * SIN(RADIANS(B32)) ) ),"ignore") -> 0.0016239005
B33: 3 | D33: =IF(ISNUMBER(F33),IF(ABS(AI33-1)<0.000001,0,IF(ABS(AI33+1)<0.000001,180,ROUND(DEGREES(ACOS(AI33)),3)))," ") -> 6.023 | F33: =IF(AG33>0.0000001,$U$8*((1/SQRT(1-AG33*AG33))-1),"none") -> 481.39499 | H33: =IF(ISNUMBER(F33),$Z$15*(1+AC33/AG33)/(1+$V$15*$Z$15*AI33)/AG33," ") -> 0.24847859 | J33: =IF(ISNUMBER(F33),IF( AND( ( (F33*(F33+2*$U$8)*AB33*AB33) > ($E$5*($E$5+2*$U$5)) ), ( B33<90 ) ), 180-AJ33, AJ33)," ") -> 3.4538717 | L33: =IF(ISNUMBER(F33),$E$5+$O$10-F33," ") -> 133.80501 | N33: =IF(ISNUMBER(P33),B33," ") -> 3 | O33: =IF(ISNUMBER(P33), IF( ABS(AM33-1)<0.000001,0, IF(ABS(AM33+1)<0.000001,180,ROUND(DEGREES(ACOS(AM33)),3)))," ") -> 180 | P33: =IF(AK33>0.0000001,$U$8*((1/SQRT(1-AK33*AK33))-1),"none") -> 0.0011100576 | Q33: =IF(ISNUMBER(P33),ABS($Z$15*(1+AC33/AK33)/(1+$V$15*$Z$15*AM33)/AK33)," ") -> 108237.48 | R33: =IF(ISNUMBER(P33),IF( AND( ( (P33*(P33+2*$U$8)*AB33*AB33) > ($E$5*($E$5+2*$U$5)) ), ( B33<90 ) ), 180-AN33, AN33)," ") -> 0.0024370945 | S33: =IF(ISNUMBER(P33),$E$5+$O$10-P33," ") -> 615.19889 | AB33: =COS(RADIANS(B33)) -> 0.99862953 | AC33: =-$V$15*AB33 -> -0.066736491 | AD33: =$AA$15+AC33*AC33 -> 1.0044267 | AF33: =AC33*AC33-AD33*$AE$15 -> 0.004426609 | AG33: =IF(ISNUMBER(SQRT(AF33)),(-AC33+SQRT(AF33))/AD33,-100) -> 0.13268191 | AH33: =(AG33*AB33-$V$15)/((1-$V$15*AG33*AB33)*$Z$15) -> 0.99448072 | AI33: =IF(ABS(AH33)<=1,AH33,IF(ABS(AH33)<=1.00001,1*SIGN(AH33),0)) -> 0.99448072 | AJ33: =DEGREES(ASIN( SQRT( (F33*(F33+2*$U$8)) / (L33*(L33+2*$U$10)) ) * SIN(RADIANS(B33)) )) -> 3.4538717 | AK33: =IF(ISNUMBER(SQRT(AF33)),(-AC33-SQRT(AF33))/AD33,-100) -> 0.00020282625 | AL33: =(AK33*AB33-$V$15)/((1-$V$15*AK33*AB33)*$Z$15) -> -0.99999999 | AM33: =IF(ABS(AL33)<=1,AL33,IF(ABS(AL33)<=1.00001,1*SIGN(AL33),0)) -> -0.99999999 | AN33: =IF(ISNUMBER(P33),DEGREES(ASIN( SQRT( (P33*(P33+2*$U$8)) / (S33*(S33+2*$U$10)) ) * SIN(RADIANS(B33)) ) ),"ignore") -> 0.0024370945
B34: 4 | D34: =IF(ISNUMBER(F34),IF(ABS(AI34-1)<0.000001,0,IF(ABS(AI34+1)<0.000001,180,ROUND(DEGREES(ACOS(AI34)),3)))," ") -> 8.03 | F34: =IF(AG34>0.0000001,$U$8*((1/SQRT(1-AG34*AG34))-1),"none") -> 480.36058 | H34: =IF(ISNUMBER(F34),$Z$15*(1+AC34/AG34)/(1+$V$15*$Z$15*AI34)/AG34," ") -> 0.24874873 | J34: =IF(ISNUMBER(F34),IF( AND( ( (F34*(F34+2*$U$8)*AB34*AB34) > ($E$5*($E$5+2*$U$5)) ), ( B34<90 ) ), 180-AJ34, AJ34)," ") -> 4.5829858 | L34: =IF(ISNUMBER(F34),$E$5+$O$10-F34," ") -> 134.83942 | N34: =IF(ISNUMBER(P34),B34," ") -> 4 | O34: =IF(ISNUMBER(P34), IF( ABS(AM34-1)<0.000001,0, IF(ABS(AM34+1)<0.000001,180,ROUND(DEGREES(ACOS(AM34)),3)))," ") -> 180 | P34: =IF(AK34>0.0000001,$U$8*((1/SQRT(1-AK34*AK34))-1),"none") -> 0.0011124374 | Q34: =IF(ISNUMBER(P34),ABS($Z$15*(1+AC34/AK34)/(1+$V$15*$Z$15*AM34)/AK34)," ") -> 107889.99 | R34: =IF(ISNUMBER(P34),IF( AND( ( (P34*(P34+2*$U$8)*AB34*AB34) > ($E$5*($E$5+2*$U$5)) ), ( B34<90 ) ), 180-AN34, AN34)," ") -> 0.0032517845 | S34: =IF(ISNUMBER(P34),$E$5+$O$10-P34," ") -> 615.19889 | AB34: =COS(RADIANS(B34)) -> 0.99756405 | AC34: =-$V$15*AB34 -> -0.066665287 | AD34: =$AA$15+AC34*AC34 -> 1.0044172 | AF34: =AC34*AC34-AD34*$AE$15 -> 0.0044171105 | AG34: =IF(ISNUMBER(SQRT(AF34)),(-AC34+SQRT(AF34))/AD34,-100) -> 0.13254117 | AH34: =(AG34*AB34-$V$15)/((1-$V$15*AG34*AB34)*$Z$15) -> 0.99019502 | AI34: =IF(ABS(AH34)<=1,AH34,IF(ABS(AH34)<=1.00001,1*SIGN(AH34),0)) -> 0.99019502 | AJ34: =DEGREES(ASIN( SQRT( (F34*(F34+2*$U$8)) / (L34*(L34+2*$U$10)) ) * SIN(RADIANS(B34)) )) -> 4.5829858 | AK34: =IF(ISNUMBER(SQRT(AF34)),(-AC34-SQRT(AF34))/AD34,-100) -> 0.00020304355 | AL34: =(AK34*AB34-$V$15)/((1-$V$15*AK34*AB34)*$Z$15) -> -0.99999998 | AM34: =IF(ABS(AL34)<=1,AL34,IF(ABS(AL34)<=1.00001,1*SIGN(AL34),0)) -> -0.99999998 | AN34: =IF(ISNUMBER(P34),DEGREES(ASIN( SQRT( (P34*(P34+2*$U$8)) / (S34*(S34+2*$U$10)) ) * SIN(RADIANS(B34)) ) ),"ignore") -> 0.0032517845
B35: 5 | D35: =IF(ISNUMBER(F35),IF(ABS(AI35-1)<0.000001,0,IF(ABS(AI35+1)<0.000001,180,ROUND(DEGREES(ACOS(AI35)),3)))," ") -> 10.037 | F35: =IF(AG35>0.0000001,$U$8*((1/SQRT(1-AG35*AG35))-1),"none") -> 479.03281 | H35: =IF(ISNUMBER(F35),$Z$15*(1+AC35/AG35)/(1+$V$15*$Z$15*AI35)/AG35," ") -> 0.24909675 | J35: =IF(ISNUMBER(F35),IF( AND( ( (F35*(F35+2*$U$8)*AB35*AB35) > ($E$5*($E$5+2*$U$5)) ), ( B35<90 ) ), 180-AJ35, AJ35)," ") -> 5.6934995 | L35: =IF(ISNUMBER(F35),$E$5+$O$10-F35," ") -> 136.16719 | N35: =IF(ISNUMBER(P35),B35," ") -> 5 | O35: =IF(ISNUMBER(P35), IF( ABS(AM35-1)<0.000001,0, IF(ABS(AM35+1)<0.000001,180,ROUND(DEGREES(ACOS(AM35)),3)))," ") -> 180 | P35: =IF(AK35>0.0000001,$U$8*((1/SQRT(1-AK35*AK35))-1),"none") -> 0.0011155072 | Q35: =IF(ISNUMBER(P35),ABS($Z$15*(1+AC35/AK35)/(1+$V$15*$Z$15*AM35)/AK35)," ") -> 107444.5 | R35: =IF(ISNUMBER(P35),IF( AND( ( (P35*(P35+2*$U$8)*AB35*AB35) > ($E$5*($E$5+2*$U$5)) ), ( B35<90 ) ), 180-AN35, AN35)," ") -> 0.0040684749 | S35: =IF(ISNUMBER(P35),$E$5+$O$10-P35," ") -> 615.19888 | AB35: =COS(RADIANS(B35)) -> 0.9961947 | AC35: =-$V$15*AB35 -> -0.066573775 | AD35: =$AA$15+AC35*AC35 -> 1.004405 | AF35: =AC35*AC35-AD35*$AE$15 -> 0.004404918 | AG35: =IF(ISNUMBER(SQRT(AF35)),(-AC35+SQRT(AF35))/AD35,-100) -> 0.13236028 | AH35: =(AG35*AB35-$V$15)/((1-$V$15*AG35*AB35)*$Z$15) -> 0.9846939 | AI35: =IF(ABS(AH35)<=1,AH35,IF(ABS(AH35)<=1.00001,1*SIGN(AH35),0)) -> 0.9846939 | AJ35: =DEGREES(ASIN( SQRT( (F35*(F35+2*$U$8)) / (L35*(L35+2*$U$10)) ) * SIN(RADIANS(B35)) )) -> 5.6934995 | AK35: =IF(ISNUMBER(SQRT(AF35)),(-AC35-SQRT(AF35))/AD35,-100) -> 0.0002033235 | AL35: =(AK35*AB35-$V$15)/((1-$V$15*AK35*AB35)*$Z$15) -> -0.99999996 | AM35: =IF(ABS(AL35)<=1,AL35,IF(ABS(AL35)<=1.00001,1*SIGN(AL35),0)) -> -0.99999996 | AN35: =IF(ISNUMBER(P35),DEGREES(ASIN( SQRT( (P35*(P35+2*$U$8)) / (S35*(S35+2*$U$10)) ) * SIN(RADIANS(B35)) ) ),"ignore") -> 0.0040684749
B36: 6 | D36: =IF(ISNUMBER(F36),IF(ABS(AI36-1)<0.000001,0,IF(ABS(AI36+1)<0.000001,180,ROUND(DEGREES(ACOS(AI36)),3)))," ") -> 12.045 | F36: =IF(AG36>0.0000001,$U$8*((1/SQRT(1-AG36*AG36))-1),"none") -> 477.41333 | H36: =IF(ISNUMBER(F36),$Z$15*(1+AC36/AG36)/(1+$V$15*$Z$15*AI36)/AG36," ") -> 0.24952319 | J36: =IF(ISNUMBER(F36),IF( AND( ( (F36*(F36+2*$U$8)*AB36*AB36) > ($E$5*($E$5+2*$U$5)) ), ( B36<90 ) ), 180-AJ36, AJ36)," ") -> 6.7812555 | L36: =IF(ISNUMBER(F36),$E$5+$O$10-F36," ") -> 137.78667 | N36: =IF(ISNUMBER(P36),B36," ") -> 6 | O36: =IF(ISNUMBER(P36), IF( ABS(AM36-1)<0.000001,0, IF(ABS(AM36+1)<0.000001,180,ROUND(DEGREES(ACOS(AM36)),3)))," ") -> 180 | P36: =IF(AK36>0.0000001,$U$8*((1/SQRT(1-AK36*AK36))-1),"none") -> 0.0011192745 | Q36: =IF(ISNUMBER(P36),ABS($Z$15*(1+AC36/AK36)/(1+$V$15*$Z$15*AM36)/AK36)," ") -> 106901.94 | R36: =IF(ISNUMBER(P36),IF( AND( ( (P36*(P36+2*$U$8)*AB36*AB36) > ($E$5*($E$5+2*$U$5)) ), ( B36<90 ) ), 180-AN36, AN36)," ") -> 0.0048876749 | S36: =IF(ISNUMBER(P36),$E$5+$O$10-P36," ") -> 615.19888 | AB36: =COS(RADIANS(B36)) -> 0.9945219 | AC36: =-$V$15*AB36 -> -0.066461985 | AD36: =$AA$15+AC36*AC36 -> 1.0043902 | AF36: =AC36*AC36-AD36*$AE$15 -> 0.0043900463 | AG36: =IF(ISNUMBER(SQRT(AF36)),(-AC36+SQRT(AF36))/AD36,-100) -> 0.1321393 | AH36: =(AG36*AB36-$V$15)/((1-$V$15*AG36*AB36)*$Z$15) -> 0.97798417 | AI36: =IF(ABS(AH36)<=1,AH36,IF(ABS(AH36)<=1.00001,1*SIGN(AH36),0)) -> 0.97798417 | AJ36: =DEGREES(ASIN( SQRT( (F36*(F36+2*$U$8)) / (L36*(L36+2*$U$10)) ) * SIN(RADIANS(B36)) )) -> 6.7812555 | AK36: =IF(ISNUMBER(SQRT(AF36)),(-AC36-SQRT(AF36))/AD36,-100) -> 0.00020366655 | AL36: =(AK36*AB36-$V$15)/((1-$V$15*AK36*AB36)*$Z$15) -> -0.99999995 | AM36: =IF(ABS(AL36)<=1,AL36,IF(ABS(AL36)<=1.00001,1*SIGN(AL36),0)) -> -0.99999995 | AN36: =IF(ISNUMBER(P36),DEGREES(ASIN( SQRT( (P36*(P36+2*$U$8)) / (S36*(S36+2*$U$10)) ) * SIN(RADIANS(B36)) ) ),"ignore") -> 0.0048876749
B37: 7 | D37: =IF(ISNUMBER(F37),IF(ABS(AI37-1)<0.000001,0,IF(ABS(AI37+1)<0.000001,180,ROUND(DEGREES(ACOS(AI37)),3)))," ") -> 14.052 | F37: =IF(AG37>0.0000001,$U$8*((1/SQRT(1-AG37*AG37))-1),"none") -> 475.50413 | H37: =IF(ISNUMBER(F37),$Z$15*(1+AC37/AG37)/(1+$V$15*$Z$15*AI37)/AG37," ") -> 0.25002868 | J37: =IF(ISNUMBER(F37),IF( AND( ( (F37*(F37+2*$U$8)*AB37*AB37) > ($E$5*($E$5+2*$U$5)) ), ( B37<90 ) ), 180-AJ37, AJ37)," ") -> 7.8424003 | L37: =IF(ISNUMBER(F37),$E$5+$O$10-F37," ") -> 139.69587 | N37: =IF(ISNUMBER(P37),B37," ") -> 7 | O37: =IF(ISNUMBER(P37), IF( ABS(AM37-1)<0.000001,0, IF(ABS(AM37+1)<0.000001,180,ROUND(DEGREES(ACOS(AM37)),3)))," ") -> 180 | P37: =IF(AK37>0.0000001,$U$8*((1/SQRT(1-AK37*AK37))-1),"none") -> 0.0011237487 | Q37: =IF(ISNUMBER(P37),ABS($Z$15*(1+AC37/AK37)/(1+$V$15*$Z$15*AM37)/AK37)," ") -> 106263.47 | R37: =IF(ISNUMBER(P37),IF( AND( ( (P37*(P37+2*$U$8)*AB37*AB37) > ($E$5*($E$5+2*$U$5)) ), ( B37<90 ) ), 180-AN37, AN37)," ") -> 0.0057099003 | S37: =IF(ISNUMBER(P37),$E$5+$O$10-P37," ") -> 615.19888 | AB37: =COS(RADIANS(B37)) -> 0.99254615 | AC37: =-$V$15*AB37 -> -0.06632995 | AD37: =$AA$15+AC37*AC37 -> 1.0043726 | AF37: =AC37*AC37-AD37*$AE$15 -> 0.0043725136 | AG37: =IF(ISNUMBER(SQRT(AF37)),(-AC37+SQRT(AF37))/AD37,-100) -> 0.13187828 | AH37: =(AG37*AB37-$V$15)/((1-$V$15*AG37*AB37)*$Z$15) -> 0.97007409 | AI37: =IF(ABS(AH37)<=1,AH37,IF(ABS(AH37)<=1.00001,1*SIGN(AH37),0)) -> 0.97007409 | AJ37: =DEGREES(ASIN( SQRT( (F37*(F37+2*$U$8)) / (L37*(L37+2*$U$10)) ) * SIN(RADIANS(B37)) )) -> 7.8424003 | AK37: =IF(ISNUMBER(SQRT(AF37)),(-AC37-SQRT(AF37))/AD37,-100) -> 0.00020407321 | AL37: =(AK37*AB37-$V$15)/((1-$V$15*AK37*AB37)*$Z$15) -> -0.99999993 | AM37: =IF(ABS(AL37)<=1,AL37,IF(ABS(AL37)<=1.00001,1*SIGN(AL37),0)) -> -0.99999993 | AN37: =IF(ISNUMBER(P37),DEGREES(ASIN( SQRT( (P37*(P37+2*$U$8)) / (S37*(S37+2*$U$10)) ) * SIN(RADIANS(B37)) ) ),"ignore") -> 0.0057099003
B38: 8 | D38: =IF(ISNUMBER(F38),IF(ABS(AI38-1)<0.000001,0,IF(ABS(AI38+1)<0.000001,180,ROUND(DEGREES(ACOS(AI38)),3)))," ") -> 16.06 | F38: =IF(AG38>0.0000001,$U$8*((1/SQRT(1-AG38*AG38))-1),"none") -> 473.30757 | H38: =IF(ISNUMBER(F38),$Z$15*(1+AC38/AG38)/(1+$V$15*$Z$15*AI38)/AG38," ") -> 0.25061402 | J38: =IF(ISNUMBER(F38),IF( AND( ( (F38*(F38+2*$U$8)*AB38*AB38) > ($E$5*($E$5+2*$U$5)) ), ( B38<90 ) ), 180-AJ38, AJ38)," ") -> 8.8734214 | L38: =IF(ISNUMBER(F38),$E$5+$O$10-F38," ") -> 141.89243 | N38: =IF(ISNUMBER(P38),B38," ") -> 8 | O38: =IF(ISNUMBER(P38), IF( ABS(AM38-1)<0.000001,0, IF(ABS(AM38+1)<0.000001,180,ROUND(DEGREES(ACOS(AM38)),3)))," ") -> 180 | P38: =IF(AK38>0.0000001,$U$8*((1/SQRT(1-AK38*AK38))-1),"none") -> 0.001128941 | Q38: =IF(ISNUMBER(P38),ABS($Z$15*(1+AC38/AK38)/(1+$V$15*$Z$15*AM38)/AK38)," ") -> 105530.46 | R38: =IF(ISNUMBER(P38),IF( AND( ( (P38*(P38+2*$U$8)*AB38*AB38) > ($E$5*($E$5+2*$U$5)) ), ( B38<90 ) ), 180-AN38, AN38)," ") -> 0.0065356739 | S38: =IF(ISNUMBER(P38),$E$5+$O$10-P38," ") -> 615.19887 | AB38: =COS(RADIANS(B38)) -> 0.99026807 | AC38: =-$V$15*AB38 -> -0.06617771 | AD38: =$AA$15+AC38*AC38 -> 1.0043525 | AF38: =AC38*AC38-AD38*$AE$15 -> 0.0043523412 | AG38: =IF(ISNUMBER(SQRT(AF38)),(-AC38+SQRT(AF38))/AD38,-100) -> 0.1315773 | AH38: =(AG38*AB38-$V$15)/((1-$V$15*AG38*AB38)*$Z$15) -> 0.96097345 | AI38: =IF(ABS(AH38)<=1,AH38,IF(ABS(AH38)<=1.00001,1*SIGN(AH38),0)) -> 0.96097345 | AJ38: =DEGREES(ASIN( SQRT( (F38*(F38+2*$U$8)) / (L38*(L38+2*$U$10)) ) * SIN(RADIANS(B38)) )) -> 8.8734214 | AK38: =IF(ISNUMBER(SQRT(AF38)),(-AC38-SQRT(AF38))/AD38,-100) -> 0.00020454413 | AL38: =(AK38*AB38-$V$15)/((1-$V$15*AK38*AB38)*$Z$15) -> -0.99999991 | AM38: =IF(ABS(AL38)<=1,AL38,IF(ABS(AL38)<=1.00001,1*SIGN(AL38),0)) -> -0.99999991 | AN38: =IF(ISNUMBER(P38),DEGREES(ASIN( SQRT( (P38*(P38+2*$U$8)) / (S38*(S38+2*$U$10)) ) * SIN(RADIANS(B38)) ) ),"ignore") -> 0.0065356739
B39: 9 | D39: =IF(ISNUMBER(F39),IF(ABS(AI39-1)<0.000001,0,IF(ABS(AI39+1)<0.000001,180,ROUND(DEGREES(ACOS(AI39)),3)))," ") -> 18.067 | F39: =IF(AG39>0.0000001,$U$8*((1/SQRT(1-AG39*AG39))-1),"none") -> 470.82636 | H39: =IF(ISNUMBER(F39),$Z$15*(1+AC39/AG39)/(1+$V$15*$Z$15*AI39)/AG39," ") -> 0.25128009 | J39: =IF(ISNUMBER(F39),IF( AND( ( (F39*(F39+2*$U$8)*AB39*AB39) > ($E$5*($E$5+2*$U$5)) ), ( B39<90 ) ), 180-AJ39, AJ39)," ") -> 9.8711756 | L39: =IF(ISNUMBER(F39),$E$5+$O$10-F39," ") -> 144.37364 | N39: =IF(ISNUMBER(P39),B39," ") -> 9 | O39: =IF(ISNUMBER(P39), IF( ABS(AM39-1)<0.000001,0, IF(ABS(AM39+1)<0.000001,180,ROUND(DEGREES(ACOS(AM39)),3)))," ") -> 180 | P39: =IF(AK39>0.0000001,$U$8*((1/SQRT(1-AK39*AK39))-1),"none") -> 0.0011348644 | Q39: =IF(ISNUMBER(P39),ABS($Z$15*(1+AC39/AK39)/(1+$V$15*$Z$15*AM39)/AK39)," ") -> 104704.47 | R39: =IF(ISNUMBER(P39),IF( AND( ( (P39*(P39+2*$U$8)*AB39*AB39) > ($E$5*($E$5+2*$U$5)) ), ( B39<90 ) ), 180-AN39, AN39)," ") -> 0.007365528 | S39: =IF(ISNUMBER(P39),$E$5+$O$10-P39," ") -> 615.19887 | AB39: =COS(RADIANS(B39)) -> 0.98768834 | AC39: =-$V$15*AB39 -> -0.066005312 | AD39: =$AA$15+AC39*AC39 -> 1.0043297 | AF39: =AC39*AC39-AD39*$AE$15 -> 0.0043295537 | AG39: =IF(ISNUMBER(SQRT(AF39)),(-AC39+SQRT(AF39))/AD39,-100) -> 0.13123645 | AH39: =(AG39*AB39-$V$15)/((1-$V$15*AG39*AB39)*$Z$15) -> 0.95069346 | AI39: =IF(ABS(AH39)<=1,AH39,IF(ABS(AH39)<=1.00001,1*SIGN(AH39),0)) -> 0.95069346 | AJ39: =DEGREES(ASIN( SQRT( (F39*(F39+2*$U$8)) / (L39*(L39+2*$U$10)) ) * SIN(RADIANS(B39)) )) -> 9.8711756 | AK39: =IF(ISNUMBER(SQRT(AF39)),(-AC39-SQRT(AF39))/AD39,-100) -> 0.00020508004 | AL39: =(AK39*AB39-$V$15)/((1-$V$15*AK39*AB39)*$Z$15) -> -0.99999988 | AM39: =IF(ABS(AL39)<=1,AL39,IF(ABS(AL39)<=1.00001,1*SIGN(AL39),0)) -> -0.99999988 | AN39: =IF(ISNUMBER(P39),DEGREES(ASIN( SQRT( (P39*(P39+2*$U$8)) / (S39*(S39+2*$U$10)) ) * SIN(RADIANS(B39)) ) ),"ignore") -> 0.007365528
B40: 10 | D40: =IF(ISNUMBER(F40),IF(ABS(AI40-1)<0.000001,0,IF(ABS(AI40+1)<0.000001,180,ROUND(DEGREES(ACOS(AI40)),3)))," ") -> 20.075 | F40: =IF(AG40>0.0000001,$U$8*((1/SQRT(1-AG40*AG40))-1),"none") -> 468.06356 | H40: =IF(ISNUMBER(F40),$Z$15*(1+AC40/AG40)/(1+$V$15*$Z$15*AI40)/AG40," ") -> 0.25202793 | J40: =IF(ISNUMBER(F40),IF( AND( ( (F40*(F40+2*$U$8)*AB40*AB40) > ($E$5*($E$5+2*$U$5)) ), ( B40<90 ) ), 180-AJ40, AJ40)," ") -> 10.832906 | L40: =IF(ISNUMBER(F40),$E$5+$O$10-F40," ") -> 147.13644 | N40: =IF(ISNUMBER(P40),B40," ") -> 10 | O40: =IF(ISNUMBER(P40), IF( ABS(AM40-1)<0.000001,0, IF(ABS(AM40+1)<0.000001,180,ROUND(DEGREES(ACOS(AM40)),3)))," ") -> 180 | P40: =IF(AK40>0.0000001,$U$8*((1/SQRT(1-AK40*AK40))-1),"none") -> 0.001141534 | Q40: =IF(ISNUMBER(P40),ABS($Z$15*(1+AC40/AK40)/(1+$V$15*$Z$15*AM40)/AK40)," ") -> 103787.23 | R40: =IF(ISNUMBER(P40),IF( AND( ( (P40*(P40+2*$U$8)*AB40*AB40) > ($E$5*($E$5+2*$U$5)) ), ( B40<90 ) ), 180-AN40, AN40)," ") -> 0.0082000049 | S40: =IF(ISNUMBER(P40),$E$5+$O$10-P40," ") -> 615.19886 | AB40: =COS(RADIANS(B40)) -> 0.98480775 | AC40: =-$V$15*AB40 -> -0.065812808 | AD40: =$AA$15+AC40*AC40 -> 1.0043043 | AF40: =AC40*AC40-AD40*$AE$15 -> 0.0043041788 | AG40: =IF(ISNUMBER(SQRT(AF40)),(-AC40+SQRT(AF40))/AD40,-100) -> 0.13085581 | AH40: =(AG40*AB40-$V$15)/((1-$V$15*AG40*AB40)*$Z$15) -> 0.93924682 | AI40: =IF(ABS(AH40)<=1,AH40,IF(ABS(AH40)<=1.00001,1*SIGN(AH40),0)) -> 0.93924682 | AJ40: =DEGREES(ASIN( SQRT( (F40*(F40+2*$U$8)) / (L40*(L40+2*$U$10)) ) * SIN(RADIANS(B40)) )) -> 10.832906 | AK40: =IF(ISNUMBER(SQRT(AF40)),(-AC40-SQRT(AF40))/AD40,-100) -> 0.00020568178 | AL40: =(AK40*AB40-$V$15)/((1-$V$15*AK40*AB40)*$Z$15) -> -0.99999986 | AM40: =IF(ABS(AL40)<=1,AL40,IF(ABS(AL40)<=1.00001,1*SIGN(AL40),0)) -> -0.99999986 | AN40: =IF(ISNUMBER(P40),DEGREES(ASIN( SQRT( (P40*(P40+2*$U$8)) / (S40*(S40+2*$U$10)) ) * SIN(RADIANS(B40)) ) ),"ignore") -> 0.0082000049
B41: 11 | D41: =IF(ISNUMBER(F41),IF(ABS(AI41-1)<0.000001,0,IF(ABS(AI41+1)<0.000001,180,ROUND(DEGREES(ACOS(AI41)),3)))," ") -> 22.082 | F41: =IF(AG41>0.0000001,$U$8*((1/SQRT(1-AG41*AG41))-1),"none") -> 465.02259 | H41: =IF(ISNUMBER(F41),$Z$15*(1+AC41/AG41)/(1+$V$15*$Z$15*AI41)/AG41," ") -> 0.2528587 | J41: =IF(ISNUMBER(F41),IF( AND( ( (F41*(F41+2*$U$8)*AB41*AB41) > ($E$5*($E$5+2*$U$5)) ), ( B41<90 ) ), 180-AJ41, AJ41)," ") -> 11.756248 | L41: =IF(ISNUMBER(F41),$E$5+$O$10-F41," ") -> 150.17741 | N41: =IF(ISNUMBER(P41),B41," ") -> 11 | O41: =IF(ISNUMBER(P41), IF( ABS(AM41-1)<0.000001,0, IF(ABS(AM41+1)<0.000001,180,ROUND(DEGREES(ACOS(AM41)),3)))," ") -> 180 | P41: =IF(AK41>0.0000001,$U$8*((1/SQRT(1-AK41*AK41))-1),"none") -> 0.0011489667 | Q41: =IF(ISNUMBER(P41),ABS($Z$15*(1+AC41/AK41)/(1+$V$15*$Z$15*AM41)/AK41)," ") -> 102780.71 | R41: =IF(ISNUMBER(P41),IF( AND( ( (P41*(P41+2*$U$8)*AB41*AB41) > ($E$5*($E$5+2*$U$5)) ), ( B41<90 ) ), 180-AN41, AN41)," ") -> 0.0090396586 | S41: =IF(ISNUMBER(P41),$E$5+$O$10-P41," ") -> 615.19885 | AB41: =COS(RADIANS(B41)) -> 0.98162718 | AC41: =-$V$15*AB41 -> -0.065600256 | AD41: =$AA$15+AC41*AC41 -> 1.0042764 | AF41: =AC41*AC41-AD41*$AE$15 -> 0.0042762475 | AG41: =IF(ISNUMBER(SQRT(AF41)),(-AC41+SQRT(AF41))/AD41,-100) -> 0.13043549 | AH41: =(AG41*AB41-$V$15)/((1-$V$15*AG41*AB41)*$Z$15) -> 0.92664764 | AI41: =IF(ABS(AH41)<=1,AH41,IF(ABS(AH41)<=1.00001,1*SIGN(AH41),0)) -> 0.92664764 | AJ41: =DEGREES(ASIN( SQRT( (F41*(F41+2*$U$8)) / (L41*(L41+2*$U$10)) ) * SIN(RADIANS(B41)) )) -> 11.756248 | AK41: =IF(ISNUMBER(SQRT(AF41)),(-AC41-SQRT(AF41))/AD41,-100) -> 0.00020635031 | AL41: =(AK41*AB41-$V$15)/((1-$V$15*AK41*AB41)*$Z$15) -> -0.99999983 | AM41: =IF(ABS(AL41)<=1,AL41,IF(ABS(AL41)<=1.00001,1*SIGN(AL41),0)) -> -0.99999983 | AN41: =IF(ISNUMBER(P41),DEGREES(ASIN( SQRT( (P41*(P41+2*$U$8)) / (S41*(S41+2*$U$10)) ) * SIN(RADIANS(B41)) ) ),"ignore") -> 0.0090396586
... B210: 180 | D210: =IF(ISNUMBER(F210),IF(ABS(AI210-1)<0.000001,0,IF(ABS(AI210+1)<0.000001,180,ROUND(DEGREES(ACOS(AI210)),3)))," ") | F210: =IF(AG210>0.0000001,$U$8*((1/SQRT(1-AG210*AG210))-1),"none") -> none | H210: =IF(ISNUMBER(F210),$Z$15*(1+AC210/AG210)/(1+$V$15*$Z$15*AI210)/AG210," ") | J210: =IF(ISNUMBER(F210),IF( AND( ( (F210*(F210+2*$U$8)*AB210*AB210) > ($E$5*($E$5+2*$U$5)) ), ( B210<90 ) ), 180-AJ210, AJ210)," ") | L210: =IF(ISNUMBER(F210),$E$5+$O$10-F210," ") | N210: =IF(ISNUMBER(P210),B210," ") | O210: =IF(ISNUMBER(P210), IF( ABS(AM210-1)<0.000001,0, IF(ABS(AM210+1)<0.000001,180,ROUND(DEGREES(ACOS(AM210)),3)))," ") | P210: =IF(AK210>0.0000001,$U$8*((1/SQRT(1-AK210*AK210))-1),"none") -> none | Q210: =IF(ISNUMBER(P210),ABS($Z$15*(1+AC210/AK210)/(1+$V$15*$Z$15*AM210)/AK210)," ") | R210: =IF(ISNUMBER(P210),IF( AND( ( (P210*(P210+2*$U$8)*AB210*AB210) > ($E$5*($E$5+2*$U$5)) ), ( B210<90 ) ), 180-AN210, AN210)," ") | S210: =IF(ISNUMBER(P210),$E$5+$O$10-P210," ") | AB210: =COS(RADIANS(B210)) -> -1 | AC210: =-$V$15*AB210 -> 0.066828076 | AD210: =$AA$15+AC210*AC210 -> 1.004439 | AF210: =AC210*AC210-AD210*$AE$15 -> 0.0044388413 | AG210: =IF(ISNUMBER(SQRT(AF210)),(-AC210+SQRT(AF210))/AD210,-100) -> -0.00020254744 | AH210: =(AG210*AB210-$V$15)/((1-$V$15*AG210*AB210)*$Z$15) -> -1 | AI210: =IF(ABS(AH210)<=1,AH210,IF(ABS(AH210)<=1.00001,1*SIGN(AH210),0)) -> -1 | AJ210: =DEGREES(ASIN( SQRT( (F210*(F210+2*$U$8)) / (L210*(L210+2*$U$10)) ) * SIN(RADIANS(B210)) )) -> #VALUE! | AK210: =IF(ISNUMBER(SQRT(AF210)),(-AC210-SQRT(AF210))/AD210,-100) -> -0.13286293 | AL210: =(AK210*AB210-$V$15)/((1-$V$15*AK210*AB210)*$Z$15) -> 1 | AM210: =IF(ABS(AL210)<=1,AL210,IF(ABS(AL210)<=1.00001,1*SIGN(AL210),0)) -> 1 | AN210: =IF(ISNUMBER(P210),DEGREES(ASIN( SQRT( (P210*(P210+2*$U$8)) / (S210*(S210+2*$U$10)) ) * SIN(RADIANS(B210)) ) ),"ignore") -> ignore

Sheet small plots
B3: ejectile lab energy | P3: solution 2
B5: angle | C5: energy | P5: angle | Q5: energy
B6: =kinematics!B16 -> 130 | C6: =kinematics!F16 -> none | P6: =B6 -> 130 | Q6: =IF(ISNUMBER(kinematics!P16),kinematics!P16,0) -> 0
B7: =kinematics!B17 -> 135 | C7: =kinematics!F17 -> none | P7: =B7 -> 135 | Q7: =IF(ISNUMBER(kinematics!P17),kinematics!P17,0) -> 0
B8: =kinematics!B18 -> 140 | C8: =kinematics!F18 -> none | P8: =B8 -> 140 | Q8: =IF(ISNUMBER(kinematics!P18),kinematics!P18,0) -> 0
B9: =kinematics!B19 -> 145 | C9: =kinematics!F19 -> none | P9: =B9 -> 145 | Q9: =IF(ISNUMBER(kinematics!P19),kinematics!P19,0) -> 0
B10: =kinematics!B20 -> 150 | C10: =kinematics!F20 -> none | P10: =B10 -> 150 | Q10: =IF(ISNUMBER(kinematics!P20),kinematics!P20,0) -> 0
B11: =kinematics!B21 -> 155 | C11: =kinematics!F21 -> none | P11: =B11 -> 155 | Q11: =IF(ISNUMBER(kinematics!P21),kinematics!P21,0) -> 0
B12: =kinematics!B22 -> 160 | C12: =kinematics!F22 -> none | P12: =B12 -> 160 | Q12: =IF(ISNUMBER(kinematics!P22),kinematics!P22,0) -> 0
B13: =kinematics!B23 -> 165 | C13: =kinematics!F23 -> none | P13: =B13 -> 165 | Q13: =IF(ISNUMBER(kinematics!P23),kinematics!P23,0) -> 0
B14: =kinematics!B24 -> 170 | C14: =kinematics!F24 -> none | P14: =B14 -> 170 | Q14: =IF(ISNUMBER(kinematics!P24),kinematics!P24,0) -> 0
B15: =kinematics!B25 -> 175 | C15: =kinematics!F25 -> none | P15: =B15 -> 175 | Q15: =IF(ISNUMBER(kinematics!P25),kinematics!P25,0) -> 0
B16: =kinematics!B26 -> 180 | C16: =kinematics!F26 -> none | P16: =B16 -> 180 | Q16: =IF(ISNUMBER(kinematics!P26),kinematics!P26,0) -> 0
B19: recoil angle
B21: =B6 -> 130 | C21: =kinematics!J16 | P21: =P6 -> 130 | Q21: =IF(ISNUMBER(kinematics!R16),kinematics!R16,0) -> 0
B22: =B7 -> 135 | C22: =kinematics!J17 | P22: =P7 -> 135 | Q22: =IF(ISNUMBER(kinematics!R17),kinematics!R17,0) -> 0
B23: =B8 -> 140 | C23: =kinematics!J18 | P23: =P8 -> 140 | Q23: =IF(ISNUMBER(kinematics!R18),kinematics!R18,0) -> 0
B24: =B9 -> 145 | C24: =kinematics!J19 | P24: =P9 -> 145 | Q24: =IF(ISNUMBER(kinematics!R19),kinematics!R19,0) -> 0
B25: =B10 -> 150 | C25: =kinematics!J20 | P25: =P10 -> 150 | Q25: =IF(ISNUMBER(kinematics!R20),kinematics!R20,0) -> 0
B26: =B11 -> 155 | C26: =kinematics!J21 | P26: =P11 -> 155 | Q26: =IF(ISNUMBER(kinematics!R21),kinematics!R21,0) -> 0
B27: =B12 -> 160 | C27: =kinematics!J22 | P27: =P12 -> 160 | Q27: =IF(ISNUMBER(kinematics!R22),kinematics!R22,0) -> 0
B28: =B13 -> 165 | C28: =kinematics!J23 | P28: =P13 -> 165 | Q28: =IF(ISNUMBER(kinematics!R23),kinematics!R23,0) -> 0
B29: =B14 -> 170 | C29: =kinematics!J24 | P29: =P14 -> 170 | Q29: =IF(ISNUMBER(kinematics!R24),kinematics!R24,0) -> 0
B30: =B15 -> 175 | C30: =kinematics!J25 | P30: =P15 -> 175 | Q30: =IF(ISNUMBER(kinematics!R25),kinematics!R25,0) -> 0
B31: =B16 -> 180 | C31: =kinematics!J26 | P31: =P16 -> 180 | Q31: =IF(ISNUMBER(kinematics!R26),kinematics!R26,0) -> 0
B34: recoil energy
B36: =B21 -> 130 | C36: =kinematics!L16 | P36: =P21 -> 130 | Q36: =kinematics!S16
B37: =B22 -> 135 | C37: =kinematics!L17 | P37: =P22 -> 135 | Q37: =kinematics!S17
B38: =B23 -> 140 | C38: =kinematics!L18 | P38: =P23 -> 140 | Q38: =kinematics!S18
B39: =B24 -> 145 | C39: =kinematics!L19 | P39: =P24 -> 145 | Q39: =kinematics!S19
B40: =B25 -> 150 | C40: =kinematics!L20 | P40: =P25 -> 150 | Q40: =kinematics!S20
B41: =B26 -> 155 | C41: =kinematics!L21 | P41: =P26 -> 155 | Q41: =kinematics!S21
B42: =B27 -> 160 | C42: =kinematics!L22 | P42: =P27 -> 160 | Q42: =kinematics!S22
B43: =B28 -> 165 | C43: =kinematics!L23 | P43: =P28 -> 165 | Q43: =kinematics!S23
B44: =B29 -> 170 | C44: =kinematics!L24 | P44: =P29 -> 170 | Q44: =kinematics!S24
B45: =B30 -> 175 | C45: =kinematics!L25 | P45: =P30 -> 175 | Q45: =kinematics!S25
B46: =B31 -> 180 | C46: =kinematics!L26 | P46: =P31 -> 180 | Q46: =kinematics!S26
B49: e vs. angle for recoil
B51: =C21 | C51: =C36 | P51: =Q21 -> 0 | Q51: =Q36
B52: =C22 | C52: =C37 | P52: =Q22 -> 0 | Q52: =Q37
...

Sheet lab angle vs cm

Sheet lab KE vs cm

Sheet CALCULATOR
B2: Mass | C2: E sep | D2: Q-value | E2: B-rho | F2: E/A | G2: sigma | H2: Brink | I2: M/Scatt | J2: Barrier | K2: Conesize | N2: Ó1998,2002,2004 W.N. Catford
B4: Mass Value
E5: n | F5: 17 | H5: D | I5: (MeV) | J5: amu | L5: MeV | N5: kg
E6: (for neutron use nn) | H6: =VLOOKUP(E5,INDIRECT(ADDRESS(MATCH(F5,A_values,0),4,1,TRUE(),"mass_rmd.mas")):INDIRECT(ADDRESS(MATCH(F5+1,A_values,0)-1,7,1,TRUE(),"mass_rmd.mas")),4,FALSE())/1000 -> 7.870079 | J6: =F5+H6/'mass_rmd.mas'!A2 -> 17.008449 | L6: =F5*'mass_rmd.mas'!A2+H6 -> 15843.397 | N6: =L6/0.511006*9.1/1E+032 -> 2.8213938e-27
B9: Separation Energy | M9: =CONCATENATE("(",E11,TEXT(F11,"0"),"/",E12,TEXT(F12,"0"),")") -> (he4/he4) | O9: =CONCATENATE("(",E10,"-",TEXT(F10,"0"),")") -> (ne-24)
E10: ne | F10: 24 | G10: Esep (MeV) | L10: D (MeV) | M10: D (MeV) | O10: D (MeV)
B11: (neutron=nn) | D11: remove | E11: he | F11: 4 | G11: =(L11+M11)-O11 -> 12.172734 | I11: =IF(AND(ISNUMBER(F11),ISTEXT(E11)),"to make"," ") -> to make | J11: =INDEX(Symbol_values,MATCH(INDEX(Z_values,MATCH(E10,Symbol_values,0))-INDEX(Z_values,MATCH(E11,Symbol_values,0)),Z_values,0)) -> O | K11: =F10-F11 -> 20 | L11: =VLOOKUP(J11,INDIRECT(ADDRESS(MATCH(K11,A_values,0),4,1,TRUE(),"mass_rmd.mas")):INDIRECT(ADDRESS(MATCH(K11+1,A_values,0)-1,7,1,TRUE(),"mass_rmd.mas")),4,FALSE())/1000 -> 3.796172 | M11: =VLOOKUP(E11,INDIRECT(ADDRESS(MATCH(F11,A_values,0),4,1,TRUE(),"mass_rmd.mas")):INDIRECT(ADDRESS(MATCH(F11+1,A_values,0)-1,7,1,TRUE(),"mass_rmd.mas")),4,FALSE())/1000 -> 2.4249156 | O11: =VLOOKUP(E10,INDIRECT(ADDRESS(MATCH(F10,A_values,0),4,1,TRUE(),"mass_rmd.mas")):INDIRECT(ADDRESS(MATCH(F10+1,A_values,0)-1,7,1,TRUE(),"mass_rmd.mas")),4,FALSE())/1000 -> -5.951646
B12: MeV to effect separation | D12: add | E12: he | F12: 4 | G12: =(O11+M12)-L12 -> 11.492115 | I12: =IF(AND(ISNUMBER(F12),ISTEXT(E12)),"to make"," ") -> to make | J12: =INDEX(Symbol_values,MATCH(INDEX(Z_values,MATCH(E10,Symbol_values,0))+INDEX(Z_values,MATCH(E12,Symbol_values,0)),Z_values,0)) -> Mg | K12: =F10+F12 -> 28 | L12: =VLOOKUP(J12,INDIRECT(ADDRESS(MATCH(K12,A_values,0),4,1,TRUE(),"mass_rmd.mas")):INDIRECT(ADDRESS(MATCH(K12+1,A_values,0)-1,7,1,TRUE(),"mass_rmd.mas")),4,FALSE())/1000 -> -15.018845 | M12: =VLOOKUP(E12,INDIRECT(ADDRESS(MATCH(F12,A_values,0),4,1,TRUE(),"mass_rmd.mas")):INDIRECT(ADDRESS(MATCH(F12+1,A_values,0)-1,7,1,TRUE(),"mass_rmd.mas")),4,FALSE())/1000 -> 2.4249156
B16: Reaction Q-value | E16: target | G16: beam | I16: ejectile | L16: recoil
B17: (Two body) | E17: be | F17: 10 | G17: h | H17: 1 | I17: he | J17: 3 | L17: =INDEX(Symbol_values,MATCH(INDEX(Z_values,MATCH(E17,Symbol_values,0))+INDEX(Z_values,MATCH(G17,Symbol_values,0))-INDEX(Z_values,MATCH(I17,Symbol_values,0)),Z_values,0)) -> Li | M17: =F17+H17-J17 -> 8
D18: D (MeV) | E18: =VLOOKUP(E17,INDIRECT(ADDRESS(MATCH(F17,A_values,0),4,1,TRUE(),"mass_rmd.mas")):INDIRECT(ADDRESS(MATCH(F17+1,A_values,0)-1,7,1,TRUE(),"mass_rmd.mas")),4,FALSE())/1000 -> 12.607488 | G18: =VLOOKUP(G17,INDIRECT(ADDRESS(MATCH(H17,A_values,0),4,1,TRUE(),"mass_rmd.mas")):INDIRECT(ADDRESS(MATCH(H17+1,A_values,0)-1,7,1,TRUE(),"mass_rmd.mas")),4,FALSE())/1000 -> 7.2889706 | I18: =VLOOKUP(I17,INDIRECT(ADDRESS(MATCH(J17,A_values,0),4,1,TRUE(),"mass_rmd.mas")):INDIRECT(ADDRESS(MATCH(J17+1,A_values,0)-1,7,1,TRUE(),"mass_rmd.mas")),4,FALSE())/1000 -> 14.931218 | L18: =VLOOKUP(L17,INDIRECT(ADDRESS(MATCH(M17,A_values,0),4,1,TRUE(),"mass_rmd.mas")):INDIRECT(ADDRESS(MATCH(M17+1,A_values,0)-1,7,1,TRUE(),"mass_rmd.mas")),4,FALSE())/1000 -> 20.945804
G19: Q-value= | H19: =E18+G18-I18-L18 -> -15.980563 | J19: MeV
G20: =CONCATENATE(INDEX(Symbol_values,MATCH(INDEX(Z_values,MATCH(E17,Symbol_values,0)),Z_values,0)),F17," ( ",INDEX(Symbol_values,MATCH(INDEX(Z_values,MATCH(G17,Symbol_values,0)),Z_values,0)),H17," , ",INDEX(Symbol_values,MATCH(INDEX(Z_values,MATCH(I17,Symbol_values,0)),Z_values,0)),J17," ) ",L17,M17) -> Be10 ( H1 , He3 ) Li8 | L20: recoil breaks up into
L21: nn | M21: 1 | N21: =INDEX(Symbol_values,MATCH(INDEX(Z_values,MATCH(L17,Symbol_values,0))-INDEX(Z_values,MATCH(L21,Symbol_values,0)),Z_values,0)) -> Li | O21: =M17-M21 -> 7
E22: (Three body:) | G22: Q-value= | H22: =E18+G18-I18-L22-N22 -> -18.013182 | J22: MeV | L22: =VLOOKUP(L21,INDIRECT(ADDRESS(MATCH(M21,A_values,0),4,1,TRUE(),"mass_rmd.mas")):INDIRECT(ADDRESS(MATCH(M21+1,A_values,0)-1,7,1,TRUE(),"mass_rmd.mas")),4,FALSE())/1000 -> 8.0713171 | N22: =VLOOKUP(N21,INDIRECT(ADDRESS(MATCH(O21,A_values,0),4,1,TRUE(),"mass_rmd.mas")):INDIRECT(ADDRESS(MATCH(O21+1,A_values,0)-1,7,1,TRUE(),"mass_rmd.mas")),4,FALSE())/1000 -> 14.907105
G23: =CONCATENATE(INDEX(Symbol_values,MATCH(INDEX(Z_values,MATCH(E17,Symbol_values,0)),Z_values,0)),F17," ( ",INDEX(Symbol_values,MATCH(INDEX(Z_values,MATCH(G17,Symbol_values,0)),Z_values,0)),H17," , ",INDEX(Symbol_values,MATCH(INDEX(Z_values,MATCH(I17,Symbol_values,0)),Z_values,0)),J17," + ",L21,M21," ) ",N21,O21) -> Be10 ( H1 , He3 + nn1 ) Li7
B25: B-rho / momentum calculator
E26: A | F26: q | H26: MeV/u | J26: MeV/A | L26: B rho (T.m)
E27: =F28+VLOOKUP(E28,INDIRECT(ADDRESS(MATCH(F28,A_values,0),4,1,TRUE(),"mass_rmd.mas")):INDIRECT(ADDRESS(MATCH(F28+1,A_values,0)-1,7,1,TRUE(),"mass_rmd.mas")),4,FALSE())/1000/'mass_rmd.mas'!$A$2 -> 37.969081 | F27: 4 | H27: =J27*F28/E27 -> 0.9609819 | J27: 0.9602 | L27: =3.10711*E27/F27*SQRT(POWER(H27/'mass_rmd.mas'!A2+1,2)-1) -> 1.3400454
D28: Ion= | E28: k | F28: 38
D29: Z= | E29: =INDEX(Z_values,MATCH(E28,Symbol_values,0)) -> 19
G30: beta= | H30: =SQRT(1-POWER((1/H32),2))*100 -> 4.538841 | J30: % | K30: KE= | L30: =H27*E27 -> 36.4876 | N30: MeV
G31: v= | H31: =H30/100*29.998 -> 1.3615615 | J31: cm/ns
E32: Flight path (m) | G32: gamma= | H32: =1+L30/(E27*'mass_rmd.mas'!A2) -> 1.0010316 | K32: p= | L32: =H32*E27*'mass_rmd.mas'!A2*H30/100/1000 -> 1.6069652 | N32: GeV/c
E33: 20 | G33: TOF= | H33: =IF(ISNUMBER(E33),E33*100/H31," ") -> 1468.9017 | J33: ns
B36: Quick E/A calculator | E36: =F37+VLOOKUP(E37,INDIRECT(ADDRESS(MATCH(F37,A_values,0),4,1,TRUE(),"mass_rmd.mas")):INDIRECT(ADDRESS(MATCH(F37+1,A_values,0)-1,7,1,TRUE(),"mass_rmd.mas")),4,FALSE())/1000/'mass_rmd.mas'!$A$2 -> 12.026922 | H36: MeV/u | J36: MeV/A | L36: MeV | N36: beta (%c)
D37: Ion= | E37: be | F37: 12 | H37: =J37*F37/E36 -> 43.901507 | J37: 44 | K37: KE= | L37: =J37*F37 -> 528 | N37: =SQRT(1-POWER((1/(1+L37/($E$36*'mass_rmd.mas'!$A$2))),2))*100 -> 29.663342
D38: Z= | E38: =INDEX(Z_values,MATCH(E37,Symbol_values,0)) -> 4 | H38: =L38/E36 -> 43.984654 | J38: =L38/F37 -> 44.083333 | K38: KE= | L38: 529 | N38: =SQRT(1-POWER((1/(1+L38/($E$36*'mass_rmd.mas'!$A$2))),2))*100 -> 29.689535
H39: 44 | J39: =H39*E36/F37 -> 44.098714 | K39: KE= | L39: =J39*F37 -> 529.18456 | N39: =SQRT(1-POWER((1/(1+L39/($E$36*'mass_rmd.mas'!$A$2))),2))*100 -> 29.694366
B42: E/A and TOF and b
B43: from B-Rho | E43: A | F43: q | H43: MeV/u | J43: MeV/A | L43: B rho
E44: =F45+VLOOKUP(E45,INDIRECT(ADDRESS(MATCH(F45,A_values,0),4,1,TRUE(),"mass_rmd.mas")):INDIRECT(ADDRESS(MATCH(F45+1,A_values,0)-1,7,1,TRUE(),"mass_rmd.mas")),4,FALSE())/1000/'mass_rmd.mas'!$A$2 -> 12.026922 | F44: 2 | H44: ='mass_rmd.mas'!A2*(SQRT(POWER( (L44/(3.10711*E44/F44)),2)+1)-1) -> 11.192547 | J44: =H44*E44/F45 -> 11.217658 | L44: 2.905156
D45: Ion= | E45: be | F45: 12
D46: Z= | E46: =INDEX(Z_values,MATCH(E45,Symbol_values,0)) -> 4
G47: beta= | H47: =SQRT(1-POWER((1/H49),2))*100 -> 15.363888 | J47: % | K47: KE= | L47: =H44*E44 -> 134.61189 | N47: MeV
G48: v = | H48: =H47/100*29.998 -> 4.6088591 | J48: cm/ns
E49: Flight path (m) | G49: gamma = | H49: =1+L47/(E44*'mass_rmd.mas'!A2) -> 1.0120156 | K49: p= | L49: =H49*E44*'mass_rmd.mas'!A2*H47/100/1000 -> 1.7419129 | N49: GeV/c
E50: 10 | G50: TOF= | H50: =IF(ISNUMBER(E50),E50*100/H48," ") -> 216.97344 | J50: ns
Q51: to TOP
B53: Cross sections and counting rates
...

Sheet plectrum plots

Sheet Plotting Sheet
A3: lab angle vs centre of mass angle | G3: lab energies vs centre of mass angle | R3: sorted | S3: data
A5: solution 1 | C5: cm angle | D5: ejectile | E5: recoil | G5: solution 1 | I5: cm angle | J5: ejectile | K5: recoil | M5: angle | N5: energy | O5: rec ang | P5: rec energy | R5: rec ang | S5: rec energy
C6: =IF(ISNUMBER(kinematics!D30),kinematics!D30,MAX(kinematics!$D$30:$D$210)) -> 0 | D6: =IF(ISNUMBER(kinematics!D30),kinematics!B30,0) -> 0 | E6: =IF(ISNUMBER(kinematics!J30),kinematics!J30,0) -> 0 | I6: =C6 -> 0 | J6: =IF(ISNUMBER(kinematics!D30),kinematics!F30,0) -> 482.72714 | K6: =IF(ISNUMBER(kinematics!L30),kinematics!L30,0) -> 132.47286 | M6: =IF(ISNUMBER(kinematics!D30),kinematics!B30,MAX($D$6:$D$186)) -> 0 | N6: =IF(ISNUMBER(kinematics!D30),kinematics!F30,0) -> 482.72714 | O6: =IF(ISNUMBER(kinematics!J30),kinematics!J30,0) -> 0 | P6: =IF(ISNUMBER(kinematics!L30),kinematics!L30,0) -> 132.47286 | R6: =O6 -> 0 | S6: =P6 -> 132.47286
